Workbook

Sheet CRM Export
A1: Номер | B1: Контрагент | C1: Назва | D1: Дата створення | E1: Статус | F1: Relevant | G1: Виконавці | H1: Service (group) | I1: Country | J1: UTM tag | K1: Google Client ID | L1: LANGUAGE | M1: Type | N1: E-mail Counterparty | O1: Reason for Rejection | P1: Name | Q1: Data event | R1: utm_term | S1: utm_medium | T1: Дата виконання | U1: Дата отримання статусу «Завершене» | V1: agreement_sent_at | W1: currency | X1: agreement_signed_at | Y1: Name | Z1: deal_value_actual | AA1: duplicate_flag | AB1: first_contact_at | AC1: first_payment_at | AD1: first_response_at | AE1: first_touch_campaign | AF1: first_touch_content | AG1: first_touch_medium | AH1: first_touch_source | AI1: first_touch_term | AJ1: full_payment_at | AK1: installments_count | AL1: lawyer_handover_at | AM1: lead_priority | AN1: lost_at | AO1: meeting_booked_at | AP1: meeting_held_at | AQ1: original_service_interest | AR1: Name | AS1: Price | AT1: Price (Persons) | AU1: payment_plan_type | AV1: payment_status | AW1: qualified_service | AX1: Name | AY1: Price | AZ1: Price (Persons) | BA1: referrer_url | BB1: source_confidence | BC1: utm_campaign | BD1: utm_content | BE1: utm_source
A2: 1671 | B2: Latvian Citizenship Lead | C2: Mr. Mohammed | D2: 45883.392 | E2: IN WORK | F2: Relevant | G2: Oleh Dymovski | H2: LV RBI Company | I2: Egypt | K2: 92654067.1755099538 | L2: EN | M2: Othe | N2: info@latviancitizenship.eu | P2: Google Ads | AA2: Ні
A3: 1701 | B3: Mohamed gadallah | C3: Mohamed gadallah | D3: 45883.678 | E3: Rejected | F3: Relevant | G3: Oleh Dymovski | H3: LV RBI Company | I3: Egypt (EG - AF) | J3: ?kw=latvia%20golden%20visa&cpn=20594231202&utm_source=google&utm_medium=cpc&utm_campaign=LV-RBI&network=s&utm_term=latvia%20golden%20visa&gad_source=5&gad_campaignid=20594231202&gclid=EAIaIQobChMIuJLSo7GKjwMVvplQBh2wMhZSEAAYASAAEgI5I_D_BwE | K3: 911467295.1755177409 | L3: EN | M3: Lead from LV email | N3: mohamedgadallah929@gmail.com | O3: NO ANSWER | P3: Google Ads | AA3: Ні
A4: 1703 | B4: Kim | C4: Kim | D4: 45883.681 | E4: IN WORK | G4: Oleh Dymovski | H4: LT citizenship | L4: RU | M4: Othe | N4: k81468824@gmail.com | AA4: Ні
A5: 1705 | B5: 曦微 | C5: 曦微 | D5: 45883.7 | E5: IN WORK | F5: Relevant | G5: Oleh Dymovski | H5: LV RBI Company | L5: EN | M5: Othe | N5: 1007317586@qq.com | P5: Other (direct email, phone call, referral etc.) | AA5: Ні
A6: 1711 | B6: Pavan | C6: Pavan | D6: 45883.787 | E6: IN WORK | G6: Oleh Dymovski | H6: LV RBI Company | L6: EN | M6: Othe | N6: pavanm.mail@gmail.com | AA6: Ні
A7: 1712 | B7: رمضان مرسي رمضان مرسي عوض الله | C7: رمضان مرسي رمضان مرسي عوض الله | D7: 45883.805 | E7: Rejected | F7: Relevant | G7: Oleh Dymovski | H7: LV RBI Company | I7: Egypt (EG - AF) | J7: ?kw=latvia%20golden%20visa&cpn=20594231202&utm_source=google&utm_medium=cpc&utm_campaign=LV-RBI&network=s&utm_term=latvia%20golden%20visa&gad_source=5&gad_campaignid=20594231202&gclid=EAIaIQobChMI2NP0htqKjwMVlJpQBh2vbwXdEAAYASAAEgKo4_D_BwE | K7: 1156971214.1755188335 | L7: EN | M7: Lead from LV email | N7: ralnjar766@gmail.com | O7: NO ANSWER | P7: Google Ads | AA7: Ні
A8: 1715 | B8: kerolis Eid | C8: kerolis Eid | D8: 45883.824 | E8: Rejected | F8: Relevant | G8: Oleh Dymovski | H8: LV RBI Company | I8: Egypt (EG - AF) | J8: ?kw=latvia%20golden%20visa&cpn=20594231202&utm_source=google&utm_medium=cpc&utm_campaign=LV-RBI&network=s&utm_term=latvia%20golden%20visa&gad_source=5&gad_campaignid=20594231202&gclid=EAIaIQobChMIzsLYxt-KjwMV7aVQBh3egiXQEAAYASAAEgIvxPD_BwE | K8: 1399949974.1755189790 | L8: EN | M8: Lead from LV email | N8: keroliseid659@gmail.com | O8: NO ANSWER | P8: Google Ads | AA8: Ні
A9: 1716 | B9: Aziz Barzani | C9: Aziz Barzani | D9: 45883.858 | E9: IN WORK | F9: Relevant | G9: Oleh Dymovski | H9: LV RBI Company | L9: EN | M9: Othe | N9: aziz.barzani74@gmail.com | P9: Google Ads | AA9: Ні
A10: 1722 | B10: محمود ابراهيم خليفة | C10: محمود ابراهيم خليفة | D10: 45883.956 | E10: Rejected | F10: Relevant | G10: Oleh Dymovski | H10: LV RBI Company | I10: Egypt (EG - AF) | J10: ?kw=latvia%20golden%20visa&cpn=20594231202&utm_source=google&utm_medium=cpc&utm_campaign=LV-RBI&network=s&utm_term=latvia%20golden%20visa&gad_source=5&gad_campaignid=20594231202&gclid=EAIaIQobChMIu5-wq4qLjwMVjVqRBR0r-jEEEAAYAiAAEgJNdfD_BwE | K10: 270380988.1755204895 | L10: EN | M10: Lead from LV email | N10: mhmad.mm5568@gmail.com | O10: NO ANSWER | P10: Google Ads | AA10: Ні
A11: 1723 | B11: Abraham monyping | C11: Abraham monyping | D11: 45883.959 | E11: Rejected | F11: No relevant | G11: Oleh Dymovski | H11: LV RBI Company | I11: Egypt (EG - AF) | J11: ?kw=latvia%20golden%20visa&cpn=20594231202&utm_source=google&utm_medium=cpc&utm_campaign=LV-RBI&network=s&utm_term=latvia%20golden%20visa&gad_source=5&gad_campaignid=20594231202&gclid=EAIaIQobChMImMmapYuLjwMVrJRQBh268TZhEAAYASAAEgJHWPD_BwE | K11: 1634999661.1755201552 | L11: EN | M11: Lead from LV email | N11: sabahabram1@gmail.com | O11: TOO EXPENSIVE | P11: Google Ads | AA11: Ні
A12: 1728 | B12: Artiom Tubaltsev | C12: Artiom Tubaltsev | D12: 45884.105 | E12: IN WORK | F12: Relevant | G12: Oleh Dymovski | H12: LT RBI | I12: Canada (CA - NA) | J12: https://www.lithuaniancitizenship.com/contact/ | K12: 1750858357.1755214043 | L12: EN | M12: Lead from LT email | N12: atuvalski@gmail.com | P12: Organic Search | AA12: Ні
A13: 1730 | B13: Mohammad Abdul Hamid | C13: Mohammad Abdul Hamid | D13: 45884.153 | E13: RETAINER AGREEMENT SENT | F13: Relevant | G13: Oleh Dymovski | H13: LT RBI | I13: Bangladesh (BD - AS) | J13: ?kw=lithuanian%20immigration%20lawyer&cpn=22728790531&utm_source=google&utm_medium=cpc&utm_campaign=LT-Lawyers-conversions&network=g&utm_term=lithuanian%20immigration%20lawyer&gad_source=1&gad_campaignid=22728790531&gbraid=0AAAAADisZv_4AdPglbSLDDQlHn | K13: 1550690838.1755217846 | L13: EN | M13: Lead from LT email | N13: muhit72@hotmail.com | P13: Google Ads | AA13: Ні
A14: 1733 | B14: Evgeny Gaivoronski | C14: Evgeny Gaivoronski | D14: 45884.312 | E14: Rejected | F14: Relevant | G14: Oleh Dymovski | H14: LT RBI | I14: Israel | L14: RU | M14: Lead from LT email | N14: evgai63@gmail.com | O14: DID NOT CONTINUE | P14: BridgeWest | AA14: Ні
A15: 1737 | B15: Maiche priscilia | C15: Maiche priscilia | D15: 45884.374 | E15: Rejected | F15: Relevant | G15: Oleh Dymovski | H15: LT RBI | I15: Camerún | K15: 696992934.1746966669 | L15: EN | M15: Lead from LT email | N15: maichepriscilia8@gmail.com | O15: TOO EXPENSIVE | P15: Google Ads | AA15: Ні
A16: 1742 | B16: Ольга | C16: Ольга | D16: 45884.456 | E16: IN WORK | F16: Relevant | G16: Oleh Dymovski | H16: LT citizenship | I16: Austria | J16: https://www.lithuaniancitizenship.com/ru/ | K16: 518572259.1755244364 | L16: RU | M16: Lead from LT email | N16: ola-ola-olya@mail.ru | P16: Organic Search | AA16: Ні
A17: 1744 | B17: Dennis Pack | C17: Dennis Pack | D17: 45884.495 | E17: IN WORK | F17: Relevant | G17: Oleh Dymovski | H17: LV RBI Company | I17: India (IN - AS) | J17: ?kw=citizenship%20by%20investment%20in%20latvia&cpn=20594231202&utm_source=google&utm_medium=cpc&utm_campaign=LV-RBI&network=s&utm_term=citizenship%20by%20investment%20in%20latvia&gad_campaignid=20594231202&wbraid=ClQKCQjwkvbEBhDjARJDANy9yupJ3MnHutHh | K17: 1487832091.1754460933 | L17: EN | M17: Lead from LV email | N17: gotoeurope1@icloud.com | P17: Google Ads | AA17: Ні
A18: 1746 | B18: Danial | C18: Danial | D18: 45884.5 | E18: Rejected | F18: Relevant | G18: Oleh Dymovski | H18: LT RBI | I18: Lithuania | L18: EN | M18: Lead from LT email | N18: support@bridgewest.eu | O18: NO ANSWER | P18: BridgeWest | AA18: Ні
A19: 1748 | B19: مروة رجب حماد رجب | C19: مروة رجب حماد رجب | D19: 45884.558 | E19: Rejected | F19: Relevant | G19: Oleh Dymovski | H19: LV RBI Company | I19: Egypt (EG - AF) | J19: ?kw=latvia%20golden%20visa&cpn=20594231202&utm_source=google&utm_medium=cpc&utm_campaign=LV-RBI&network=s&utm_term=latvia%20golden%20visa&gad_source=5&gad_campaignid=20594231202&gclid=EAIaIQobChMI96vptcyMjwMV1qNQBh2ZOQG2EAAYASAAEgK40_D_BwE | K19: 48694705.1755253395 | L19: EN | M19: Lead from LV email | N19: marwaragabragab0@gmail.com | O19: NO ANSWER | P19: Google Ads | AA19: Ні
A20: 1750 | B20: shahid mehmood | C20: shahid mehmood | D20: 45884.565 | E20: Rejected | F20: No relevant | G20: Oleh Dymovski | H20: LT RBI | I20: España | J20: https://www.lithuaniancitizenship.com/immigration-lawyers-in-lithuania/?kw=lawyers%20in%20lithuania&cpn=22728790531&utm_source=google&utm_medium=cpc&utm_campaign=LT-Lawyers-conversions&network=g&utm_term=lawyers%20in%20lithuania&gad_source=1&gad_campaigni | K20: 1194724387.1755254015 | L20: EN | M20: Lead from LT email | N20: shahid6076@gmail.com | O20: ANOTHER REASON | P20: Google Ads | AA20: Ні
A21: 1751 | B21: Abdallah Salem | C21: Abdallah Salem | D21: 45884.583 | E21: Rejected | F21: No relevant | G21: Oleh Dymovski | H21: LT RBI | L21: EN | M21: Lead from LT email | N21: abdullah.hatem300@gmail.com | O21: TOO EXPENSIVE | P21: BridgeWest | AA21: Ні
A22: 1752 | B22: Ar.Hasan khan | C22: Ar.Hasan khan | D22: 45884.59 | E22: Rejected | F22: Relevant | G22: Oleh Dymovski | H22: LT RBI | I22: India (IN - AS) | J22: https://www.lithuaniancitizenship.com/ | L22: EN | M22: Lead from LT email | N22: hasankhan1222@gmail.com | O22: NO ANSWER | P22: Organic Search | AA22: Ні
A23: 1760 | B23: SHEMASIYA | C23: SHEMASIYA | D23: 45884.71 | E23: Rejected | F23: Relevant | G23: Oleh Dymovski | H23: LV RBI Company | I23: Saudi Arabia (SA - AS) | J23: https://latviancitizenship.eu/thank_you/ | K23: 1983506755.1755266403 | L23: EN | M23: Lead from LV email | N23: Arsinallovi@gmail.com | O23: NO ANSWER | P23: Google Ads | AA23: Ні
A24: 1763 | B24: مروة رجب حماد رجب | C24: مروة رجب حماد رجب | D24: 45884.737 | E24: Rejected | F24: Relevant | G24: Oleh Dymovski | H24: LV RBI Company | I24: Egypt (EG - AF) | J24: ?kw=latvia%20golden%20visa&cpn=20594231202&utm_source=google&utm_medium=cpc&utm_campaign=LV-RBI&network=s&utm_term=latvia%20golden%20visa&gad_source=5&gad_campaignid=20594231202&gclid=EAIaIQobChMI9auEhIaNjwMVGppQBh25kA81EAAYASAAEgJkOPD_BwE | K24: 48694705.1755253395 | L24: EN | M24: Lead from LT email | N24: marwaragabragab0@gmail.com | O24: SPAM | P24: Google Ads | AA24: Ні
A25: 1773 | B25: Игнат | C25: Игнат | D25: 45885.038 | E25: IN WORK | F25: Relevant | G25: Oleh Dymovski | H25: LT citizenship | L25: RU | M25: Lead from LT email | N25: ignatsbkoo@gmail.com | P25: Organic Search | AA25: Ні
A26: 1774 | B26: SLEGERIS | C26: SLEGERIS | D26: 45885.104 | E26: Rejected | F26: No relevant | G26: Oleh Dymovski | H26: Company Formation | I26: Poland | L26: EN | M26: Lead from LT email | N26: vinc.wis001@gmail.com | O26: DID NOT CONTINUE | P26: BridgeWest | AA26: Ні
A27: 1778 | B27: Hawouazaid | C27: Hawouazaid | D27: 45885.226 | E27: Rejected | F27: Relevant | G27: Oleh Dymovski | H27: LV RBI Company | I27: Egypt (EG - AF) | J27: ?kw=latvia%20golden%20visa&cpn=20594231202&utm_source=google&utm_medium=cpc&utm_campaign=LV-RBI&network=s&utm_term=latvia%20golden%20visa&gad_source=5&gad_campaignid=20594231202&gclid=EAIaIQobChMIoajk-aKOjwMVtZJQBh0jjjzFEAAYASAAEgISxfD_BwE | K27: 1947068726.1755299687 | L27: EN | M27: Lead from LV email | N27: zaidmoussa@gmail.com | O27: NO ANSWER | P27: Google Ads | AA27: Ні
A28: 1782 | B28: Prasad Rai | C28: Prasad Rai | D28: 45885.319 | E28: Rejected | F28: No relevant | G28: Oleh Dymovski | H28: LT RBI | I28: Nepal | J28: ?kw=lawyers%20in%20lithuania&cpn=22728790531&utm_source=google&utm_medium=cpc&utm_campaign=LT-Lawyers-conversions&network=g&utm_term=lawyers%20in%20lithuania&gad_source=1&gad_campaignid=22728790531&gclid=CjwKCAjwtfvEBhAmEiwA-DsKjmN6CmUv2o3NYgQfnfrT6q | L28: EN | M28: Lead from LT email | N28: prarai@gmail.com | P28: Google Ads | AA28: Ні
A29: 1786 | B29: Angel V Augustine | C29: Angel V Augustine | D29: 45885.525 | E29: Rejected | F29: Relevant | G29: Oleh Dymovski | H29: LT RBI | I29: India (IN - AS) | K29: undefined | L29: EN | M29: Lead from LT email | N29: angel.augustine26@gmail.com | O29: NO ANSWER | P29: Facebook | AA29: Ні
A30: 1789 | B30: Bruce N Oderman | C30: Bruce N Oderman | D30: 45885.651 | E30: Rejected | F30: Relevant | G30: Oleh Dymovski | H30: LV RBI Real Estate | I30: United States (US - NA) | J30: ?kw=how%20to%20move%20to%20latvia&cpn=14711890461&campaignid=14711890461&adgroupid=136078623308&keywordid=%7Bkeywordid%7D&network=g&device=m&gad_source=1&gad_campaignid=14711890461&gclid=Cj0KCQjw2IDFBhDCARIsABDKOJ4lh5gf41ekFmK5M1T-fLcOIcm4_9gRrdMtevS | K30: 515491682.1755347606 | L30: EN | M30: Lead from LV email | N30: bnoderman@gmail.com | O30: NO ANSWER | P30: Google Ads | AA30: Ні
A31: 1793 | B31: Юргайтис Андрей Валерьевич | C31: Юргайтис Андрей Валерьевич | D31: 45885.782 | E31: IN WORK | F31: Relevant | G31: Oleh Dymovski | H31: LT citizenship | I31: Россия (RU - EU) | J31: https://www.lithuaniancitizenship.com/ru/lithuania-dual-citizenship/ | K31: 1375497709.1755358035 | L31: RU | M31: Lead from LT email | N31: yurgaitis.1987@mail.ru | P31: Organic Search | AA31: Ні
A32: 1795 | B32: محمود عبد الرحمن محمود خلف الله | C32: محمود عبد الرحمن محمود خلف الله | D32: 45885.813 | E32: Rejected | F32: Relevant | G32: Oleh Dymovski | H32: LV RBI Company | I32: Egypt (EG - AF) | J32: ?kw=latvia%20golden%20visa&cpn=20594231202&utm_source=google&utm_medium=cpc&utm_campaign=LV-RBI&network=s&utm_term=latvia%20golden%20visa&gad_source=5&gad_campaignid=20594231202&gclid=EAIaIQobChMI0ae1reCPjwMVI49QBh3mFB-XEAAYASAAEgJ4QfD_BwE | K32: 1566641718.1755361831 | L32: EN | M32: Lead from LV email | N32: mahmoud20202425@gmail.com | O32: NO ANSWER | P32: Google Ads | AA32: Ні
A33: 1799 | B33: Nvjggj | C33: Nvjggj | D33: 45885.838 | E33: Rejected | F33: Relevant | G33: Oleh Dymovski | H33: LV RBI Company | I33: Egypt (EG - AF) | J33: ?kw=latvia%20golden%20visa&cpn=20594231202&utm_source=google&utm_medium=cpc&utm_campaign=LV-RBI&network=s&utm_term=latvia%20golden%20visa&gad_source=5&gad_campaignid=20594231202&gclid=EAIaIQobChMI8c2mnOiPjwMVEplQBh1hBx1DEAAYASAAEgJjp_D_BwE | K33: 1704104201.1755367490 | L33: EN | M33: Lead from LV email | N33: saidsaa890@gmail.com | O33: NO ANSWER | P33: Google Ads | AA33: Ні
A34: 1803 | B34: Mohamed aden daud | C34: Mohamed aden daud | D34: 45885.872 | E34: Rejected | F34: No relevant | G34: Oleksandr Mostovyi, Oleh Dymovski | H34: LV RBI Company | I34: Angola (AO - AF) | J34: ?kw=latvia%20residence%20permit&cpn=20594231202&utm_source=google&utm_medium=cpc&utm_campaign=LV-RBI&network=s&utm_term=latvia%20residence%20permit&gad_source=5&gad_campaignid=20594231202&gclid=EAIaIQobChMI9K7FrPOPjwMVAp9aBR0gXBNTEAAYASABEgKzUfD_BwE | K34: 865917060.1755366929 | L34: EN | M34: Lead from LT email | N34: ibrahimmuhumeddaud@gmail.com | O34: TOO EXPENSIVE | P34: Google Ads | AA34: Ні
A35: 1810 | B35: Syed | C35: Syed | D35: 45885.902 | E35: IN WORK | F35: Relevant | G35: Oleh Dymovski | H35: LV RBI Company | I35: France (FR - EU) | J35: ?kw=latvia%20residency%20by%20investment&cpn=20594231202&utm_source=google&utm_medium=cpc&utm_campaign=LV-RBI&network=g&utm_term=latvia%20residency%20by%20investment&gad_source=1&gad_campaignid=20594231202&gbraid=0AAAAADisZv87tpZD601mz5zYZP-inxgsH&gc | K35: 1986795887.1755369299 | L35: EN | M35: Lead from LV email | N35: urooj@gmx.com | P35: Google Ads | AA35: Ні
A36: 1813 | B36: Monday Godwin | C36: Monday Godwin | D36: 45886.062 | E36: IN WORK | F36: Relevant | G36: Oleh Dymovski | H36: LT RBI | I36: Nigeria (NG - AF) | K36: 99924364.1755383116 | L36: EN | M36: Lead from LT email | N36: mudiaville@yahoo.co.uk | P36: Google Ads | AA36: Ні
A37: 1814 | B37: Jason Porter | C37: Jason Porter | D37: 45886.084 | E37: IN WORK | F37: Relevant | G37: Oleh Dymovski | H37: LV RBI Company | I37: United States (US - NA) | J37: ?kw=latvia%20citizenship%20by%20investment&cpn=22658494721&utm_source=google&utm_medium=cpc&utm_campaign=LV-RB-TOPI&network=g&utm_term=latvia%20citizenship%20by%20investment&gad_source=1&gad_campaignid=22658494721&gbraid=0AAAAADisZv-2i5M2476UIvLn-jPV | K37: 1741712433.1755385206 | L37: EN | M37: Lead from LV email | N37: jajporter@yahoo.com | P37: Google Ads | AA37: Ні
A38: 1816 | B38: Abdalla hellal abdalla Hassan | C38: Abdalla hellal abdalla Hassan | D38: 45886.341 | E38: Rejected | F38: Relevant | G38: Oleh Dymovski | H38: LV RBI Company | I38: Egypt (EG - AF) | J38: ?kw=latvia%20golden%20visa&cpn=20594231202&utm_source=google&utm_medium=cpc&utm_campaign=LV-RBI&network=s&utm_term=latvia%20golden%20visa&gad_source=5&gad_campaignid=20594231202&gclid=EAIaIQobChMI9pGXp4qRjwMV95ZQBh1UVSn3EAAYASAAEgLxTvD_BwE | K38: 31494120.1755407445 | L38: EN | M38: Lead from LV email | N38: abdallahelal788@gmail.com | O38: Non-relevant lead | P38: Google Ads | AA38: Ні
A39: 1820 | B39: Hassan Ahmed | C39: Hassan Ahmed | D39: 45886.515 | E39: Rejected | F39: Relevant | G39: Oleh Dymovski | H39: LV RBI Company | I39: Egypt (EG - AF) | J39: ?kw=latvia%20golden%20visa&cpn=20594231202&utm_source=google&utm_medium=cpc&utm_campaign=LV-RBI&network=s&utm_term=latvia%20golden%20visa&gad_source=5&gad_campaignid=20594231202&gclid=EAIaIQobChMIiM2pnMKRjwMVuYpQBh0mpB9UEAAYASAAEgKy4PD_BwE | K39: 435908056.1755425978 | L39: EN | M39: Lead from LV email | N39: hkarba03@gmail.com | O39: NO ANSWER | P39: Google Ads | AA39: Ні
A40: 1821 | B40: JAMES ODONG | C40: JAMES ODONG | D40: 45886.651 | E40: IN WORK | F40: No relevant | G40: Oleh Dymovski | H40: LT RBI | I40: Uganda (UG - AF) | K40: 1147808336.1755434210 | L40: EN | M40: Lead from LT email | N40: odongoliver@yahoo.co.uk | P40: Google Ads | AA40: Ні
...

Sheet Dashboard
A1: CRM Analytics MVP Dashboard
A3: How to use
A4: Replace the data rows in sheet "CRM Export" with a new export in the same column order. All report sheets will update automatically.
A6: Important note: agreement/payment date fields are currently mostly empty in CRM. Until they start populating, pipeline payment metrics below are partly based on status proxies.
A10: Total leads | B10: =COUNTA('CRM Export'!A:A)-1 | D10: Relevant rate | E10: =IFERROR(B13/B10,0) | G10: Field implementation coverage
A11: Period start | B11: =MIN('CRM Export'!D:D) | D11: Rejected rate | E11: =IFERROR(B14/B10,0) | G11: UTM tag raw | H11: =COUNTIF('CRM Export'!J:J,"<>")-1 | I11: =IFERROR(H11/$B$10,0)
A12: Period end | B12: =MAX('CRM Export'!D:D) | D12: Google share of leads | E12: =IFERROR(B16/B10,0) | G12: Google Client ID | H12: =COUNTIF('CRM Export'!K:K,"<>")-1 | I12: =IFERROR(H12/$B$10,0)
A13: Relevant leads | B13: =COUNTIF('CRM Export'!F:F,"Relevant") | D13: BridgeWest share | E13: =IFERROR(B17/B10,0) | G13: utm_term | H13: =COUNTIF('CRM Export'!R:R,"<>")-1 | I13: =IFERROR(H13/$B$10,0)
A14: Rejected leads | B14: =COUNTIF('CRM Export'!E:E,"Rejected") | D14: Organic share | E14: =IFERROR(B18/B10,0) | G14: utm_medium | H14: =COUNTIF('CRM Export'!S:S,"<>")-1 | I14: =IFERROR(H14/$B$10,0)
A15: Active pipeline | B15: =COUNTIFS('CRM Export'!A:A,"<>",'CRM Export'!E:E,"<>Rejected",'CRM Export'!E:E,"<>Завершене") | D15: Country fill rate | E15: =IFERROR(B21/B10,0) | G15: agreement_sent_at | H15: =COUNTIF('CRM Export'!V:V,"<>")-1 | I15: =IFERROR(H15/$B$10,0)
A16: Google Ads leads | B16: =COUNTIF('CRM Export'!P:P,"Google Ads") | G16: agreement_signed_at | H16: =COUNTIF('CRM Export'!X:X,"<>")-1 | I16: =IFERROR(H16/$B$10,0)
A17: BridgeWest leads | B17: =COUNTIF('CRM Export'!P:P,"BridgeWest") | G17: currency | H17: =COUNTIF('CRM Export'!W:W,"<>")-1 | I17: =IFERROR(H17/$B$10,0)
A18: Organic Search leads | B18: =COUNTIF('CRM Export'!P:P,"Organic Search") | G18: deal_value_actual | H18: =COUNTIF('CRM Export'!Z:Z,"<>")-1 | I18: =IFERROR(H18/$B$10,0)
A19: Website Form leads | B19: =COUNTIF('CRM Export'!P:P,"Website Form")
A20: Emails captured | B20: =COUNTA('CRM Export'!N:N)-1
A21: Countries filled | B21: =COUNTIF('CRM Export'!I:I,"<>")-1

Sheet Monthly Trend
A1: Monthly trend
A3: Month | B3: Leads | C3: Relevant | D3: Rejected | E3: In Work | F3: Google Ads | G3: BridgeWest | H3: Organic | I3: Website Form | J3: Agreement Sent (status/date) | K3: Initial Payment (status) | L3: Full Payment (status) | M3: Completed
A4: 45870 | B4: =COUNTIFS('CRM Export'!$D:$D,">="&DATE(YEAR(A4),MONTH(A4),1),'CRM Export'!$D:$D,"<"&EDATE(A4,1)) | C4: =COUNTIFS('CRM Export'!$D:$D,">="&DATE(YEAR(A4),MONTH(A4),1),'CRM Export'!$D:$D,"<"&EDATE(A4,1),'CRM Export'!$F:$F,"Relevant") | D4: =COUNTIFS('CRM Export'!$D:$D,">="&DATE(YEAR(A4),MONTH(A4),1),'CRM Export'!$D:$D,"<"&EDATE(A4,1),'CRM Export'!$E:$E,"Rejected") | E4: =COUNTIFS('CRM Export'!$D:$D,">="&DATE(YEAR(A4),MONTH(A4),1),'CRM Export'!$D:$D,"<"&EDATE(A4,1),'CRM Export'!$E:$E,"IN WORK") | F4: =COUNTIFS('CRM Export'!$D:$D,">="&DATE(YEAR(A4),MONTH(A4),1),'CRM Export'!$D:$D,"<"&EDATE(A4,1),'CRM Export'!$P:$P,"Google Ads") | G4: =COUNTIFS('CRM Export'!$D:$D,">="&DATE(YEAR(A4),MONTH(A4),1),'CRM Export'!$D:$D,"<"&EDATE(A4,1),'CRM Export'!$P:$P,"BridgeWest") | H4: =COUNTIFS('CRM Export'!$D:$D,">="&DATE(YEAR(A4),MONTH(A4),1),'CRM Export'!$D:$D,"<"&EDATE(A4,1),'CRM Export'!$P:$P,"Organic Search") | I4: =COUNTIFS('CRM Export'!$D:$D,">="&DATE(YEAR(A4),MONTH(A4),1),'CRM Export'!$D:$D,"<"&EDATE(A4,1),'CRM Export'!$P:$P,"Website Form") | J4: =COUNTIFS('CRM Export'!$D:$D,">="&DATE(YEAR(A4),MONTH(A4),1),'CRM Export'!$D:$D,"<"&EDATE(A4,1),'CRM Export'!$E:$E,"RETAINER AGREEMENT SENT")+COUNTIFS('CRM Export'!$V:$V,">="&DATE(YEAR(A4),MONTH(A4),1),'CRM Export'!$V:$V,"<"&EDATE(A4,1)) | K4: =COUNTIFS('CRM Export'!$D:$D,">="&DATE(YEAR(A4),MONTH(A4),1),'CRM Export'!$D:$D,"<"&EDATE(A4,1),'CRM Export'!$E:$E,"INITIAL PAYMENT RECEIVED") | L4: =COUNTIFS('CRM Export'!$D:$D,">="&DATE(YEAR(A4),MONTH(A4),1),'CRM Export'!$D:$D,"<"&EDATE(A4,1),'CRM Export'!$E:$E,"FULL PAYMENT IS MADE") | M4: =COUNTIFS('CRM Export'!$D:$D,">="&DATE(YEAR(A4),MONTH(A4),1),'CRM Export'!$D:$D,"<"&EDATE(A4,1),'CRM Export'!$E:$E,"Завершене")
A5: 45901 | B5: =COUNTIFS('CRM Export'!$D:$D,">="&DATE(YEAR(A5),MONTH(A5),1),'CRM Export'!$D:$D,"<"&EDATE(A5,1)) | C5: =COUNTIFS('CRM Export'!$D:$D,">="&DATE(YEAR(A5),MONTH(A5),1),'CRM Export'!$D:$D,"<"&EDATE(A5,1),'CRM Export'!$F:$F,"Relevant") | D5: =COUNTIFS('CRM Export'!$D:$D,">="&DATE(YEAR(A5),MONTH(A5),1),'CRM Export'!$D:$D,"<"&EDATE(A5,1),'CRM Export'!$E:$E,"Rejected") | E5: =COUNTIFS('CRM Export'!$D:$D,">="&DATE(YEAR(A5),MONTH(A5),1),'CRM Export'!$D:$D,"<"&EDATE(A5,1),'CRM Export'!$E:$E,"IN WORK") | F5: =COUNTIFS('CRM Export'!$D:$D,">="&DATE(YEAR(A5),MONTH(A5),1),'CRM Export'!$D:$D,"<"&EDATE(A5,1),'CRM Export'!$P:$P,"Google Ads") | G5: =COUNTIFS('CRM Export'!$D:$D,">="&DATE(YEAR(A5),MONTH(A5),1),'CRM Export'!$D:$D,"<"&EDATE(A5,1),'CRM Export'!$P:$P,"BridgeWest") | H5: =COUNTIFS('CRM Export'!$D:$D,">="&DATE(YEAR(A5),MONTH(A5),1),'CRM Export'!$D:$D,"<"&EDATE(A5,1),'CRM Export'!$P:$P,"Organic Search") | I5: =COUNTIFS('CRM Export'!$D:$D,">="&DATE(YEAR(A5),MONTH(A5),1),'CRM Export'!$D:$D,"<"&EDATE(A5,1),'CRM Export'!$P:$P,"Website Form") | J5: =COUNTIFS('CRM Export'!$D:$D,">="&DATE(YEAR(A5),MONTH(A5),1),'CRM Export'!$D:$D,"<"&EDATE(A5,1),'CRM Export'!$E:$E,"RETAINER AGREEMENT SENT")+COUNTIFS('CRM Export'!$V:$V,">="&DATE(YEAR(A5),MONTH(A5),1),'CRM Export'!$V:$V,"<"&EDATE(A5,1)) | K5: =COUNTIFS('CRM Export'!$D:$D,">="&DATE(YEAR(A5),MONTH(A5),1),'CRM Export'!$D:$D,"<"&EDATE(A5,1),'CRM Export'!$E:$E,"INITIAL PAYMENT RECEIVED") | L5: =COUNTIFS('CRM Export'!$D:$D,">="&DATE(YEAR(A5),MONTH(A5),1),'CRM Export'!$D:$D,"<"&EDATE(A5,1),'CRM Export'!$E:$E,"FULL PAYMENT IS MADE") | M5: =COUNTIFS('CRM Export'!$D:$D,">="&DATE(YEAR(A5),MONTH(A5),1),'CRM Export'!$D:$D,"<"&EDATE(A5,1),'CRM Export'!$E:$E,"Завершене")
A6: 45931 | B6: =COUNTIFS('CRM Export'!$D:$D,">="&DATE(YEAR(A6),MONTH(A6),1),'CRM Export'!$D:$D,"<"&EDATE(A6,1)) | C6: =COUNTIFS('CRM Export'!$D:$D,">="&DATE(YEAR(A6),MONTH(A6),1),'CRM Export'!$D:$D,"<"&EDATE(A6,1),'CRM Export'!$F:$F,"Relevant") | D6: =COUNTIFS('CRM Export'!$D:$D,">="&DATE(YEAR(A6),MONTH(A6),1),'CRM Export'!$D:$D,"<"&EDATE(A6,1),'CRM Export'!$E:$E,"Rejected") | E6: =COUNTIFS('CRM Export'!$D:$D,">="&DATE(YEAR(A6),MONTH(A6),1),'CRM Export'!$D:$D,"<"&EDATE(A6,1),'CRM Export'!$E:$E,"IN WORK") | F6: =COUNTIFS('CRM Export'!$D:$D,">="&DATE(YEAR(A6),MONTH(A6),1),'CRM Export'!$D:$D,"<"&EDATE(A6,1),'CRM Export'!$P:$P,"Google Ads") | G6: =COUNTIFS('CRM Export'!$D:$D,">="&DATE(YEAR(A6),MONTH(A6),1),'CRM Export'!$D:$D,"<"&EDATE(A6,1),'CRM Export'!$P:$P,"BridgeWest") | H6: =COUNTIFS('CRM Export'!$D:$D,">="&DATE(YEAR(A6),MONTH(A6),1),'CRM Export'!$D:$D,"<"&EDATE(A6,1),'CRM Export'!$P:$P,"Organic Search") | I6: =COUNTIFS('CRM Export'!$D:$D,">="&DATE(YEAR(A6),MONTH(A6),1),'CRM Export'!$D:$D,"<"&EDATE(A6,1),'CRM Export'!$P:$P,"Website Form") | J6: =COUNTIFS('CRM Export'!$D:$D,">="&DATE(YEAR(A6),MONTH(A6),1),'CRM Export'!$D:$D,"<"&EDATE(A6,1),'CRM Export'!$E:$E,"RETAINER AGREEMENT SENT")+COUNTIFS('CRM Export'!$V:$V,">="&DATE(YEAR(A6),MONTH(A6),1),'CRM Export'!$V:$V,"<"&EDATE(A6,1)) | K6: =COUNTIFS('CRM Export'!$D:$D,">="&DATE(YEAR(A6),MONTH(A6),1),'CRM Export'!$D:$D,"<"&EDATE(A6,1),'CRM Export'!$E:$E,"INITIAL PAYMENT RECEIVED") | L6: =COUNTIFS('CRM Export'!$D:$D,">="&DATE(YEAR(A6),MONTH(A6),1),'CRM Export'!$D:$D,"<"&EDATE(A6,1),'CRM Export'!$E:$E,"FULL PAYMENT IS MADE") | M6: =COUNTIFS('CRM Export'!$D:$D,">="&DATE(YEAR(A6),MONTH(A6),1),'CRM Export'!$D:$D,"<"&EDATE(A6,1),'CRM Export'!$E:$E,"Завершене")
A7: 45962 | B7: =COUNTIFS('CRM Export'!$D:$D,">="&DATE(YEAR(A7),MONTH(A7),1),'CRM Export'!$D:$D,"<"&EDATE(A7,1)) | C7: =COUNTIFS('CRM Export'!$D:$D,">="&DATE(YEAR(A7),MONTH(A7),1),'CRM Export'!$D:$D,"<"&EDATE(A7,1),'CRM Export'!$F:$F,"Relevant") | D7: =COUNTIFS('CRM Export'!$D:$D,">="&DATE(YEAR(A7),MONTH(A7),1),'CRM Export'!$D:$D,"<"&EDATE(A7,1),'CRM Export'!$E:$E,"Rejected") | E7: =COUNTIFS('CRM Export'!$D:$D,">="&DATE(YEAR(A7),MONTH(A7),1),'CRM Export'!$D:$D,"<"&EDATE(A7,1),'CRM Export'!$E:$E,"IN WORK") | F7: =COUNTIFS('CRM Export'!$D:$D,">="&DATE(YEAR(A7),MONTH(A7),1),'CRM Export'!$D:$D,"<"&EDATE(A7,1),'CRM Export'!$P:$P,"Google Ads") | G7: =COUNTIFS('CRM Export'!$D:$D,">="&DATE(YEAR(A7),MONTH(A7),1),'CRM Export'!$D:$D,"<"&EDATE(A7,1),'CRM Export'!$P:$P,"BridgeWest") | H7: =COUNTIFS('CRM Export'!$D:$D,">="&DATE(YEAR(A7),MONTH(A7),1),'CRM Export'!$D:$D,"<"&EDATE(A7,1),'CRM Export'!$P:$P,"Organic Search") | I7: =COUNTIFS('CRM Export'!$D:$D,">="&DATE(YEAR(A7),MONTH(A7),1),'CRM Export'!$D:$D,"<"&EDATE(A7,1),'CRM Export'!$P:$P,"Website Form") | J7: =COUNTIFS('CRM Export'!$D:$D,">="&DATE(YEAR(A7),MONTH(A7),1),'CRM Export'!$D:$D,"<"&EDATE(A7,1),'CRM Export'!$E:$E,"RETAINER AGREEMENT SENT")+COUNTIFS('CRM Export'!$V:$V,">="&DATE(YEAR(A7),MONTH(A7),1),'CRM Export'!$V:$V,"<"&EDATE(A7,1)) | K7: =COUNTIFS('CRM Export'!$D:$D,">="&DATE(YEAR(A7),MONTH(A7),1),'CRM Export'!$D:$D,"<"&EDATE(A7,1),'CRM Export'!$E:$E,"INITIAL PAYMENT RECEIVED") | L7: =COUNTIFS('CRM Export'!$D:$D,">="&DATE(YEAR(A7),MONTH(A7),1),'CRM Export'!$D:$D,"<"&EDATE(A7,1),'CRM Export'!$E:$E,"FULL PAYMENT IS MADE") | M7: =COUNTIFS('CRM Export'!$D:$D,">="&DATE(YEAR(A7),MONTH(A7),1),'CRM Export'!$D:$D,"<"&EDATE(A7,1),'CRM Export'!$E:$E,"Завершене")
A8: 45992 | B8: =COUNTIFS('CRM Export'!$D:$D,">="&DATE(YEAR(A8),MONTH(A8),1),'CRM Export'!$D:$D,"<"&EDATE(A8,1)) | C8: =COUNTIFS('CRM Export'!$D:$D,">="&DATE(YEAR(A8),MONTH(A8),1),'CRM Export'!$D:$D,"<"&EDATE(A8,1),'CRM Export'!$F:$F,"Relevant") | D8: =COUNTIFS('CRM Export'!$D:$D,">="&DATE(YEAR(A8),MONTH(A8),1),'CRM Export'!$D:$D,"<"&EDATE(A8,1),'CRM Export'!$E:$E,"Rejected") | E8: =COUNTIFS('CRM Export'!$D:$D,">="&DATE(YEAR(A8),MONTH(A8),1),'CRM Export'!$D:$D,"<"&EDATE(A8,1),'CRM Export'!$E:$E,"IN WORK") | F8: =COUNTIFS('CRM Export'!$D:$D,">="&DATE(YEAR(A8),MONTH(A8),1),'CRM Export'!$D:$D,"<"&EDATE(A8,1),'CRM Export'!$P:$P,"Google Ads") | G8: =COUNTIFS('CRM Export'!$D:$D,">="&DATE(YEAR(A8),MONTH(A8),1),'CRM Export'!$D:$D,"<"&EDATE(A8,1),'CRM Export'!$P:$P,"BridgeWest") | H8: =COUNTIFS('CRM Export'!$D:$D,">="&DATE(YEAR(A8),MONTH(A8),1),'CRM Export'!$D:$D,"<"&EDATE(A8,1),'CRM Export'!$P:$P,"Organic Search") | I8: =COUNTIFS('CRM Export'!$D:$D,">="&DATE(YEAR(A8),MONTH(A8),1),'CRM Export'!$D:$D,"<"&EDATE(A8,1),'CRM Export'!$P:$P,"Website Form") | J8: =COUNTIFS('CRM Export'!$D:$D,">="&DATE(YEAR(A8),MONTH(A8),1),'CRM Export'!$D:$D,"<"&EDATE(A8,1),'CRM Export'!$E:$E,"RETAINER AGREEMENT SENT")+COUNTIFS('CRM Export'!$V:$V,">="&DATE(YEAR(A8),MONTH(A8),1),'CRM Export'!$V:$V,"<"&EDATE(A8,1)) | K8: =COUNTIFS('CRM Export'!$D:$D,">="&DATE(YEAR(A8),MONTH(A8),1),'CRM Export'!$D:$D,"<"&EDATE(A8,1),'CRM Export'!$E:$E,"INITIAL PAYMENT RECEIVED") | L8: =COUNTIFS('CRM Export'!$D:$D,">="&DATE(YEAR(A8),MONTH(A8),1),'CRM Export'!$D:$D,"<"&EDATE(A8,1),'CRM Export'!$E:$E,"FULL PAYMENT IS MADE") | M8: =COUNTIFS('CRM Export'!$D:$D,">="&DATE(YEAR(A8),MONTH(A8),1),'CRM Export'!$D:$D,"<"&EDATE(A8,1),'CRM Export'!$E:$E,"Завершене")
A9: 46023 | B9: =COUNTIFS('CRM Export'!$D:$D,">="&DATE(YEAR(A9),MONTH(A9),1),'CRM Export'!$D:$D,"<"&EDATE(A9,1)) | C9: =COUNTIFS('CRM Export'!$D:$D,">="&DATE(YEAR(A9),MONTH(A9),1),'CRM Export'!$D:$D,"<"&EDATE(A9,1),'CRM Export'!$F:$F,"Relevant") | D9: =COUNTIFS('CRM Export'!$D:$D,">="&DATE(YEAR(A9),MONTH(A9),1),'CRM Export'!$D:$D,"<"&EDATE(A9,1),'CRM Export'!$E:$E,"Rejected") | E9: =COUNTIFS('CRM Export'!$D:$D,">="&DATE(YEAR(A9),MONTH(A9),1),'CRM Export'!$D:$D,"<"&EDATE(A9,1),'CRM Export'!$E:$E,"IN WORK") | F9: =COUNTIFS('CRM Export'!$D:$D,">="&DATE(YEAR(A9),MONTH(A9),1),'CRM Export'!$D:$D,"<"&EDATE(A9,1),'CRM Export'!$P:$P,"Google Ads") | G9: =COUNTIFS('CRM Export'!$D:$D,">="&DATE(YEAR(A9),MONTH(A9),1),'CRM Export'!$D:$D,"<"&EDATE(A9,1),'CRM Export'!$P:$P,"BridgeWest") | H9: =COUNTIFS('CRM Export'!$D:$D,">="&DATE(YEAR(A9),MONTH(A9),1),'CRM Export'!$D:$D,"<"&EDATE(A9,1),'CRM Export'!$P:$P,"Organic Search") | I9: =COUNTIFS('CRM Export'!$D:$D,">="&DATE(YEAR(A9),MONTH(A9),1),'CRM Export'!$D:$D,"<"&EDATE(A9,1),'CRM Export'!$P:$P,"Website Form") | J9: =COUNTIFS('CRM Export'!$D:$D,">="&DATE(YEAR(A9),MONTH(A9),1),'CRM Export'!$D:$D,"<"&EDATE(A9,1),'CRM Export'!$E:$E,"RETAINER AGREEMENT SENT")+COUNTIFS('CRM Export'!$V:$V,">="&DATE(YEAR(A9),MONTH(A9),1),'CRM Export'!$V:$V,"<"&EDATE(A9,1)) | K9: =COUNTIFS('CRM Export'!$D:$D,">="&DATE(YEAR(A9),MONTH(A9),1),'CRM Export'!$D:$D,"<"&EDATE(A9,1),'CRM Export'!$E:$E,"INITIAL PAYMENT RECEIVED") | L9: =COUNTIFS('CRM Export'!$D:$D,">="&DATE(YEAR(A9),MONTH(A9),1),'CRM Export'!$D:$D,"<"&EDATE(A9,1),'CRM Export'!$E:$E,"FULL PAYMENT IS MADE") | M9: =COUNTIFS('CRM Export'!$D:$D,">="&DATE(YEAR(A9),MONTH(A9),1),'CRM Export'!$D:$D,"<"&EDATE(A9,1),'CRM Export'!$E:$E,"Завершене")
A10: 46054 | B10: =COUNTIFS('CRM Export'!$D:$D,">="&DATE(YEAR(A10),MONTH(A10),1),'CRM Export'!$D:$D,"<"&EDATE(A10,1)) | C10: =COUNTIFS('CRM Export'!$D:$D,">="&DATE(YEAR(A10),MONTH(A10),1),'CRM Export'!$D:$D,"<"&EDATE(A10,1),'CRM Export'!$F:$F,"Relevant") | D10: =COUNTIFS('CRM Export'!$D:$D,">="&DATE(YEAR(A10),MONTH(A10),1),'CRM Export'!$D:$D,"<"&EDATE(A10,1),'CRM Export'!$E:$E,"Rejected") | E10: =COUNTIFS('CRM Export'!$D:$D,">="&DATE(YEAR(A10),MONTH(A10),1),'CRM Export'!$D:$D,"<"&EDATE(A10,1),'CRM Export'!$E:$E,"IN WORK") | F10: =COUNTIFS('CRM Export'!$D:$D,">="&DATE(YEAR(A10),MONTH(A10),1),'CRM Export'!$D:$D,"<"&EDATE(A10,1),'CRM Export'!$P:$P,"Google Ads") | G10: =COUNTIFS('CRM Export'!$D:$D,">="&DATE(YEAR(A10),MONTH(A10),1),'CRM Export'!$D:$D,"<"&EDATE(A10,1),'CRM Export'!$P:$P,"BridgeWest") | H10: =COUNTIFS('CRM Export'!$D:$D,">="&DATE(YEAR(A10),MONTH(A10),1),'CRM Export'!$D:$D,"<"&EDATE(A10,1),'CRM Export'!$P:$P,"Organic Search") | I10: =COUNTIFS('CRM Export'!$D:$D,">="&DATE(YEAR(A10),MONTH(A10),1),'CRM Export'!$D:$D,"<"&EDATE(A10,1),'CRM Export'!$P:$P,"Website Form") | J10: =COUNTIFS('CRM Export'!$D:$D,">="&DATE(YEAR(A10),MONTH(A10),1),'CRM Export'!$D:$D,"<"&EDATE(A10,1),'CRM Export'!$E:$E,"RETAINER AGREEMENT SENT")+COUNTIFS('CRM Export'!$V:$V,">="&DATE(YEAR(A10),MONTH(A10),1),'CRM Export'!$V:$V,"<"&EDATE(A10,1)) | K10: =COUNTIFS('CRM Export'!$D:$D,">="&DATE(YEAR(A10),MONTH(A10),1),'CRM Export'!$D:$D,"<"&EDATE(A10,1),'CRM Export'!$E:$E,"INITIAL PAYMENT RECEIVED") | L10: =COUNTIFS('CRM Export'!$D:$D,">="&DATE(YEAR(A10),MONTH(A10),1),'CRM Export'!$D:$D,"<"&EDATE(A10,1),'CRM Export'!$E:$E,"FULL PAYMENT IS MADE") | M10: =COUNTIFS('CRM Export'!$D:$D,">="&DATE(YEAR(A10),MONTH(A10),1),'CRM Export'!$D:$D,"<"&EDATE(A10,1),'CRM Export'!$E:$E,"Завершене")
A11: 46082 | B11: =COUNTIFS('CRM Export'!$D:$D,">="&DATE(YEAR(A11),MONTH(A11),1),'CRM Export'!$D:$D,"<"&EDATE(A11,1)) | C11: =COUNTIFS('CRM Export'!$D:$D,">="&DATE(YEAR(A11),MONTH(A11),1),'CRM Export'!$D:$D,"<"&EDATE(A11,1),'CRM Export'!$F:$F,"Relevant") | D11: =COUNTIFS('CRM Export'!$D:$D,">="&DATE(YEAR(A11),MONTH(A11),1),'CRM Export'!$D:$D,"<"&EDATE(A11,1),'CRM Export'!$E:$E,"Rejected") | E11: =COUNTIFS('CRM Export'!$D:$D,">="&DATE(YEAR(A11),MONTH(A11),1),'CRM Export'!$D:$D,"<"&EDATE(A11,1),'CRM Export'!$E:$E,"IN WORK") | F11: =COUNTIFS('CRM Export'!$D:$D,">="&DATE(YEAR(A11),MONTH(A11),1),'CRM Export'!$D:$D,"<"&EDATE(A11,1),'CRM Export'!$P:$P,"Google Ads") | G11: =COUNTIFS('CRM Export'!$D:$D,">="&DATE(YEAR(A11),MONTH(A11),1),'CRM Export'!$D:$D,"<"&EDATE(A11,1),'CRM Export'!$P:$P,"BridgeWest") | H11: =COUNTIFS('CRM Export'!$D:$D,">="&DATE(YEAR(A11),MONTH(A11),1),'CRM Export'!$D:$D,"<"&EDATE(A11,1),'CRM Export'!$P:$P,"Organic Search") | I11: =COUNTIFS('CRM Export'!$D:$D,">="&DATE(YEAR(A11),MONTH(A11),1),'CRM Export'!$D:$D,"<"&EDATE(A11,1),'CRM Export'!$P:$P,"Website Form") | J11: =COUNTIFS('CRM Export'!$D:$D,">="&DATE(YEAR(A11),MONTH(A11),1),'CRM Export'!$D:$D,"<"&EDATE(A11,1),'CRM Export'!$E:$E,"RETAINER AGREEMENT SENT")+COUNTIFS('CRM Export'!$V:$V,">="&DATE(YEAR(A11),MONTH(A11),1),'CRM Export'!$V:$V,"<"&EDATE(A11,1)) | K11: =COUNTIFS('CRM Export'!$D:$D,">="&DATE(YEAR(A11),MONTH(A11),1),'CRM Export'!$D:$D,"<"&EDATE(A11,1),'CRM Export'!$E:$E,"INITIAL PAYMENT RECEIVED") | L11: =COUNTIFS('CRM Export'!$D:$D,">="&DATE(YEAR(A11),MONTH(A11),1),'CRM Export'!$D:$D,"<"&EDATE(A11,1),'CRM Export'!$E:$E,"FULL PAYMENT IS MADE") | M11: =COUNTIFS('CRM Export'!$D:$D,">="&DATE(YEAR(A11),MONTH(A11),1),'CRM Export'!$D:$D,"<"&EDATE(A11,1),'CRM Export'!$E:$E,"Завершене")
A12: 46113 | B12: =COUNTIFS('CRM Export'!$D:$D,">="&DATE(YEAR(A12),MONTH(A12),1),'CRM Export'!$D:$D,"<"&EDATE(A12,1)) | C12: =COUNTIFS('CRM Export'!$D:$D,">="&DATE(YEAR(A12),MONTH(A12),1),'CRM Export'!$D:$D,"<"&EDATE(A12,1),'CRM Export'!$F:$F,"Relevant") | D12: =COUNTIFS('CRM Export'!$D:$D,">="&DATE(YEAR(A12),MONTH(A12),1),'CRM Export'!$D:$D,"<"&EDATE(A12,1),'CRM Export'!$E:$E,"Rejected") | E12: =COUNTIFS('CRM Export'!$D:$D,">="&DATE(YEAR(A12),MONTH(A12),1),'CRM Export'!$D:$D,"<"&EDATE(A12,1),'CRM Export'!$E:$E,"IN WORK") | F12: =COUNTIFS('CRM Export'!$D:$D,">="&DATE(YEAR(A12),MONTH(A12),1),'CRM Export'!$D:$D,"<"&EDATE(A12,1),'CRM Export'!$P:$P,"Google Ads") | G12: =COUNTIFS('CRM Export'!$D:$D,">="&DATE(YEAR(A12),MONTH(A12),1),'CRM Export'!$D:$D,"<"&EDATE(A12,1),'CRM Export'!$P:$P,"BridgeWest") | H12: =COUNTIFS('CRM Export'!$D:$D,">="&DATE(YEAR(A12),MONTH(A12),1),'CRM Export'!$D:$D,"<"&EDATE(A12,1),'CRM Export'!$P:$P,"Organic Search") | I12: =COUNTIFS('CRM Export'!$D:$D,">="&DATE(YEAR(A12),MONTH(A12),1),'CRM Export'!$D:$D,"<"&EDATE(A12,1),'CRM Export'!$P:$P,"Website Form") | J12: =COUNTIFS('CRM Export'!$D:$D,">="&DATE(YEAR(A12),MONTH(A12),1),'CRM Export'!$D:$D,"<"&EDATE(A12,1),'CRM Export'!$E:$E,"RETAINER AGREEMENT SENT")+COUNTIFS('CRM Export'!$V:$V,">="&DATE(YEAR(A12),MONTH(A12),1),'CRM Export'!$V:$V,"<"&EDATE(A12,1)) | K12: =COUNTIFS('CRM Export'!$D:$D,">="&DATE(YEAR(A12),MONTH(A12),1),'CRM Export'!$D:$D,"<"&EDATE(A12,1),'CRM Export'!$E:$E,"INITIAL PAYMENT RECEIVED") | L12: =COUNTIFS('CRM Export'!$D:$D,">="&DATE(YEAR(A12),MONTH(A12),1),'CRM Export'!$D:$D,"<"&EDATE(A12,1),'CRM Export'!$E:$E,"FULL PAYMENT IS MADE") | M12: =COUNTIFS('CRM Export'!$D:$D,">="&DATE(YEAR(A12),MONTH(A12),1),'CRM Export'!$D:$D,"<"&EDATE(A12,1),'CRM Export'!$E:$E,"Завершене")
A13: 46143 | B13: =COUNTIFS('CRM Export'!$D:$D,">="&DATE(YEAR(A13),MONTH(A13),1),'CRM Export'!$D:$D,"<"&EDATE(A13,1)) | C13: =COUNTIFS('CRM Export'!$D:$D,">="&DATE(YEAR(A13),MONTH(A13),1),'CRM Export'!$D:$D,"<"&EDATE(A13,1),'CRM Export'!$F:$F,"Relevant") | D13: =COUNTIFS('CRM Export'!$D:$D,">="&DATE(YEAR(A13),MONTH(A13),1),'CRM Export'!$D:$D,"<"&EDATE(A13,1),'CRM Export'!$E:$E,"Rejected") | E13: =COUNTIFS('CRM Export'!$D:$D,">="&DATE(YEAR(A13),MONTH(A13),1),'CRM Export'!$D:$D,"<"&EDATE(A13,1),'CRM Export'!$E:$E,"IN WORK") | F13: =COUNTIFS('CRM Export'!$D:$D,">="&DATE(YEAR(A13),MONTH(A13),1),'CRM Export'!$D:$D,"<"&EDATE(A13,1),'CRM Export'!$P:$P,"Google Ads") | G13: =COUNTIFS('CRM Export'!$D:$D,">="&DATE(YEAR(A13),MONTH(A13),1),'CRM Export'!$D:$D,"<"&EDATE(A13,1),'CRM Export'!$P:$P,"BridgeWest") | H13: =COUNTIFS('CRM Export'!$D:$D,">="&DATE(YEAR(A13),MONTH(A13),1),'CRM Export'!$D:$D,"<"&EDATE(A13,1),'CRM Export'!$P:$P,"Organic Search") | I13: =COUNTIFS('CRM Export'!$D:$D,">="&DATE(YEAR(A13),MONTH(A13),1),'CRM Export'!$D:$D,"<"&EDATE(A13,1),'CRM Export'!$P:$P,"Website Form") | J13: =COUNTIFS('CRM Export'!$D:$D,">="&DATE(YEAR(A13),MONTH(A13),1),'CRM Export'!$D:$D,"<"&EDATE(A13,1),'CRM Export'!$E:$E,"RETAINER AGREEMENT SENT")+COUNTIFS('CRM Export'!$V:$V,">="&DATE(YEAR(A13),MONTH(A13),1),'CRM Export'!$V:$V,"<"&EDATE(A13,1)) | K13: =COUNTIFS('CRM Export'!$D:$D,">="&DATE(YEAR(A13),MONTH(A13),1),'CRM Export'!$D:$D,"<"&EDATE(A13,1),'CRM Export'!$E:$E,"INITIAL PAYMENT RECEIVED") | L13: =COUNTIFS('CRM Export'!$D:$D,">="&DATE(YEAR(A13),MONTH(A13),1),'CRM Export'!$D:$D,"<"&EDATE(A13,1),'CRM Export'!$E:$E,"FULL PAYMENT IS MADE") | M13: =COUNTIFS('CRM Export'!$D:$D,">="&DATE(YEAR(A13),MONTH(A13),1),'CRM Export'!$D:$D,"<"&EDATE(A13,1),'CRM Export'!$E:$E,"Завершене")
A14: 46174 | B14: =COUNTIFS('CRM Export'!$D:$D,">="&DATE(YEAR(A14),MONTH(A14),1),'CRM Export'!$D:$D,"<"&EDATE(A14,1)) | C14: =COUNTIFS('CRM Export'!$D:$D,">="&DATE(YEAR(A14),MONTH(A14),1),'CRM Export'!$D:$D,"<"&EDATE(A14,1),'CRM Export'!$F:$F,"Relevant") | D14: =COUNTIFS('CRM Export'!$D:$D,">="&DATE(YEAR(A14),MONTH(A14),1),'CRM Export'!$D:$D,"<"&EDATE(A14,1),'CRM Export'!$E:$E,"Rejected") | E14: =COUNTIFS('CRM Export'!$D:$D,">="&DATE(YEAR(A14),MONTH(A14),1),'CRM Export'!$D:$D,"<"&EDATE(A14,1),'CRM Export'!$E:$E,"IN WORK") | F14: =COUNTIFS('CRM Export'!$D:$D,">="&DATE(YEAR(A14),MONTH(A14),1),'CRM Export'!$D:$D,"<"&EDATE(A14,1),'CRM Export'!$P:$P,"Google Ads") | G14: =COUNTIFS('CRM Export'!$D:$D,">="&DATE(YEAR(A14),MONTH(A14),1),'CRM Export'!$D:$D,"<"&EDATE(A14,1),'CRM Export'!$P:$P,"BridgeWest") | H14: =COUNTIFS('CRM Export'!$D:$D,">="&DATE(YEAR(A14),MONTH(A14),1),'CRM Export'!$D:$D,"<"&EDATE(A14,1),'CRM Export'!$P:$P,"Organic Search") | I14: =COUNTIFS('CRM Export'!$D:$D,">="&DATE(YEAR(A14),MONTH(A14),1),'CRM Export'!$D:$D,"<"&EDATE(A14,1),'CRM Export'!$P:$P,"Website Form") | J14: =COUNTIFS('CRM Export'!$D:$D,">="&DATE(YEAR(A14),MONTH(A14),1),'CRM Export'!$D:$D,"<"&EDATE(A14,1),'CRM Export'!$E:$E,"RETAINER AGREEMENT SENT")+COUNTIFS('CRM Export'!$V:$V,">="&DATE(YEAR(A14),MONTH(A14),1),'CRM Export'!$V:$V,"<"&EDATE(A14,1)) | K14: =COUNTIFS('CRM Export'!$D:$D,">="&DATE(YEAR(A14),MONTH(A14),1),'CRM Export'!$D:$D,"<"&EDATE(A14,1),'CRM Export'!$E:$E,"INITIAL PAYMENT RECEIVED") | L14: =COUNTIFS('CRM Export'!$D:$D,">="&DATE(YEAR(A14),MONTH(A14),1),'CRM Export'!$D:$D,"<"&EDATE(A14,1),'CRM Export'!$E:$E,"FULL PAYMENT IS MADE") | M14: =COUNTIFS('CRM Export'!$D:$D,">="&DATE(YEAR(A14),MONTH(A14),1),'CRM Export'!$D:$D,"<"&EDATE(A14,1),'CRM Export'!$E:$E,"Завершене")
A15: 46204 | B15: =COUNTIFS('CRM Export'!$D:$D,">="&DATE(YEAR(A15),MONTH(A15),1),'CRM Export'!$D:$D,"<"&EDATE(A15,1)) | C15: =COUNTIFS('CRM Export'!$D:$D,">="&DATE(YEAR(A15),MONTH(A15),1),'CRM Export'!$D:$D,"<"&EDATE(A15,1),'CRM Export'!$F:$F,"Relevant") | D15: =COUNTIFS('CRM Export'!$D:$D,">="&DATE(YEAR(A15),MONTH(A15),1),'CRM Export'!$D:$D,"<"&EDATE(A15,1),'CRM Export'!$E:$E,"Rejected") | E15: =COUNTIFS('CRM Export'!$D:$D,">="&DATE(YEAR(A15),MONTH(A15),1),'CRM Export'!$D:$D,"<"&EDATE(A15,1),'CRM Export'!$E:$E,"IN WORK") | F15: =COUNTIFS('CRM Export'!$D:$D,">="&DATE(YEAR(A15),MONTH(A15),1),'CRM Export'!$D:$D,"<"&EDATE(A15,1),'CRM Export'!$P:$P,"Google Ads") | G15: =COUNTIFS('CRM Export'!$D:$D,">="&DATE(YEAR(A15),MONTH(A15),1),'CRM Export'!$D:$D,"<"&EDATE(A15,1),'CRM Export'!$P:$P,"BridgeWest") | H15: =COUNTIFS('CRM Export'!$D:$D,">="&DATE(YEAR(A15),MONTH(A15),1),'CRM Export'!$D:$D,"<"&EDATE(A15,1),'CRM Export'!$P:$P,"Organic Search") | I15: =COUNTIFS('CRM Export'!$D:$D,">="&DATE(YEAR(A15),MONTH(A15),1),'CRM Export'!$D:$D,"<"&EDATE(A15,1),'CRM Export'!$P:$P,"Website Form") | J15: =COUNTIFS('CRM Export'!$D:$D,">="&DATE(YEAR(A15),MONTH(A15),1),'CRM Export'!$D:$D,"<"&EDATE(A15,1),'CRM Export'!$E:$E,"RETAINER AGREEMENT SENT")+COUNTIFS('CRM Export'!$V:$V,">="&DATE(YEAR(A15),MONTH(A15),1),'CRM Export'!$V:$V,"<"&EDATE(A15,1)) | K15: =COUNTIFS('CRM Export'!$D:$D,">="&DATE(YEAR(A15),MONTH(A15),1),'CRM Export'!$D:$D,"<"&EDATE(A15,1),'CRM Export'!$E:$E,"INITIAL PAYMENT RECEIVED") | L15: =COUNTIFS('CRM Export'!$D:$D,">="&DATE(YEAR(A15),MONTH(A15),1),'CRM Export'!$D:$D,"<"&EDATE(A15,1),'CRM Export'!$E:$E,"FULL PAYMENT IS MADE") | M15: =COUNTIFS('CRM Export'!$D:$D,">="&DATE(YEAR(A15),MONTH(A15),1),'CRM Export'!$D:$D,"<"&EDATE(A15,1),'CRM Export'!$E:$E,"Завершене")
... A21: 46388 | B21: =COUNTIFS('CRM Export'!$D:$D,">="&DATE(YEAR(A21),MONTH(A21),1),'CRM Export'!$D:$D,"<"&EDATE(A21,1)) | C21: =COUNTIFS('CRM Export'!$D:$D,">="&DATE(YEAR(A21),MONTH(A21),1),'CRM Export'!$D:$D,"<"&EDATE(A21,1),'CRM Export'!$F:$F,"Relevant") | D21: =COUNTIFS('CRM Export'!$D:$D,">="&DATE(YEAR(A21),MONTH(A21),1),'CRM Export'!$D:$D,"<"&EDATE(A21,1),'CRM Export'!$E:$E,"Rejected") | E21: =COUNTIFS('CRM Export'!$D:$D,">="&DATE(YEAR(A21),MONTH(A21),1),'CRM Export'!$D:$D,"<"&EDATE(A21,1),'CRM Export'!$E:$E,"IN WORK") | F21: =COUNTIFS('CRM Export'!$D:$D,">="&DATE(YEAR(A21),MONTH(A21),1),'CRM Export'!$D:$D,"<"&EDATE(A21,1),'CRM Export'!$P:$P,"Google Ads") | G21: =COUNTIFS('CRM Export'!$D:$D,">="&DATE(YEAR(A21),MONTH(A21),1),'CRM Export'!$D:$D,"<"&EDATE(A21,1),'CRM Export'!$P:$P,"BridgeWest") | H21: =COUNTIFS('CRM Export'!$D:$D,">="&DATE(YEAR(A21),MONTH(A21),1),'CRM Export'!$D:$D,"<"&EDATE(A21,1),'CRM Export'!$P:$P,"Organic Search") | I21: =COUNTIFS('CRM Export'!$D:$D,">="&DATE(YEAR(A21),MONTH(A21),1),'CRM Export'!$D:$D,"<"&EDATE(A21,1),'CRM Export'!$P:$P,"Website Form") | J21: =COUNTIFS('CRM Export'!$D:$D,">="&DATE(YEAR(A21),MONTH(A21),1),'CRM Export'!$D:$D,"<"&EDATE(A21,1),'CRM Export'!$E:$E,"RETAINER AGREEMENT SENT")+COUNTIFS('CRM Export'!$V:$V,">="&DATE(YEAR(A21),MONTH(A21),1),'CRM Export'!$V:$V,"<"&EDATE(A21,1)) | K21: =COUNTIFS('CRM Export'!$D:$D,">="&DATE(YEAR(A21),MONTH(A21),1),'CRM Export'!$D:$D,"<"&EDATE(A21,1),'CRM Export'!$E:$E,"INITIAL PAYMENT RECEIVED") | L21: =COUNTIFS('CRM Export'!$D:$D,">="&DATE(YEAR(A21),MONTH(A21),1),'CRM Export'!$D:$D,"<"&EDATE(A21,1),'CRM Export'!$E:$E,"FULL PAYMENT IS MADE") | M21: =COUNTIFS('CRM Export'!$D:$D,">="&DATE(YEAR(A21),MONTH(A21),1),'CRM Export'!$D:$D,"<"&EDATE(A21,1),'CRM Export'!$E:$E,"Завершене")

Sheet Source Report
A1: Source report
A3: Source | B3: Leads | C3: Share | D3: Relevant | E3: Relevant rate | F3: Rejected | G3: Rejection rate | H3: Countries | I3: Services
A4: Google Ads | B4: =COUNTIF('CRM Export'!$P:$P,A4) | C4: =IFERROR(B4/Dashboard!$B$10,0) | D4: =COUNTIFS('CRM Export'!$P:$P,A4,'CRM Export'!$F:$F,"Relevant") | E4: =IFERROR(D4/B4,0) | F4: =COUNTIFS('CRM Export'!$P:$P,A4,'CRM Export'!$E:$E,"Rejected") | G4: =IFERROR(F4/B4,0) | H4: n/a | I4: n/a
A5: Website Form | B5: =COUNTIF('CRM Export'!$P:$P,A5) | C5: =IFERROR(B5/Dashboard!$B$10,0) | D5: =COUNTIFS('CRM Export'!$P:$P,A5,'CRM Export'!$F:$F,"Relevant") | E5: =IFERROR(D5/B5,0) | F5: =COUNTIFS('CRM Export'!$P:$P,A5,'CRM Export'!$E:$E,"Rejected") | G5: =IFERROR(F5/B5,0) | H5: n/a | I5: n/a
A6: BridgeWest | B6: =COUNTIF('CRM Export'!$P:$P,A6) | C6: =IFERROR(B6/Dashboard!$B$10,0) | D6: =COUNTIFS('CRM Export'!$P:$P,A6,'CRM Export'!$F:$F,"Relevant") | E6: =IFERROR(D6/B6,0) | F6: =COUNTIFS('CRM Export'!$P:$P,A6,'CRM Export'!$E:$E,"Rejected") | G6: =IFERROR(F6/B6,0) | H6: n/a | I6: n/a
A7: Organic Search | B7: =COUNTIF('CRM Export'!$P:$P,A7) | C7: =IFERROR(B7/Dashboard!$B$10,0) | D7: =COUNTIFS('CRM Export'!$P:$P,A7,'CRM Export'!$F:$F,"Relevant") | E7: =IFERROR(D7/B7,0) | F7: =COUNTIFS('CRM Export'!$P:$P,A7,'CRM Export'!$E:$E,"Rejected") | G7: =IFERROR(F7/B7,0) | H7: n/a | I7: n/a
A8: Other (direct email, phone call, referral etc.) | B8: =COUNTIF('CRM Export'!$P:$P,A8) | C8: =IFERROR(B8/Dashboard!$B$10,0) | D8: =COUNTIFS('CRM Export'!$P:$P,A8,'CRM Export'!$F:$F,"Relevant") | E8: =IFERROR(D8/B8,0) | F8: =COUNTIFS('CRM Export'!$P:$P,A8,'CRM Export'!$E:$E,"Rejected") | G8: =IFERROR(F8/B8,0) | H8: n/a | I8: n/a
A9: Bing Ads | B9: =COUNTIF('CRM Export'!$P:$P,A9) | C9: =IFERROR(B9/Dashboard!$B$10,0) | D9: =COUNTIFS('CRM Export'!$P:$P,A9,'CRM Export'!$F:$F,"Relevant") | E9: =IFERROR(D9/B9,0) | F9: =COUNTIFS('CRM Export'!$P:$P,A9,'CRM Export'!$E:$E,"Rejected") | G9: =IFERROR(F9/B9,0) | H9: n/a | I9: n/a
A10: Facebook | B10: =COUNTIF('CRM Export'!$P:$P,A10) | C10: =IFERROR(B10/Dashboard!$B$10,0) | D10: =COUNTIFS('CRM Export'!$P:$P,A10,'CRM Export'!$F:$F,"Relevant") | E10: =IFERROR(D10/B10,0) | F10: =COUNTIFS('CRM Export'!$P:$P,A10,'CRM Export'!$E:$E,"Rejected") | G10: =IFERROR(F10/B10,0) | H10: n/a | I10: n/a
A11: AI (ChatGPT etc.) | B11: =COUNTIF('CRM Export'!$P:$P,A11) | C11: =IFERROR(B11/Dashboard!$B$10,0) | D11: =COUNTIFS('CRM Export'!$P:$P,A11,'CRM Export'!$F:$F,"Relevant") | E11: =IFERROR(D11/B11,0) | F11: =COUNTIFS('CRM Export'!$P:$P,A11,'CRM Export'!$E:$E,"Rejected") | G11: =IFERROR(F11/B11,0) | H11: n/a | I11: n/a
A12: Tik Tok | B12: =COUNTIF('CRM Export'!$P:$P,A12) | C12: =IFERROR(B12/Dashboard!$B$10,0) | D12: =COUNTIFS('CRM Export'!$P:$P,A12,'CRM Export'!$F:$F,"Relevant") | E12: =IFERROR(D12/B12,0) | F12: =COUNTIFS('CRM Export'!$P:$P,A12,'CRM Export'!$E:$E,"Rejected") | G12: =IFERROR(F12/B12,0) | H12: n/a | I12: n/a
A13: Newsletter | B13: =COUNTIF('CRM Export'!$P:$P,A13) | C13: =IFERROR(B13/Dashboard!$B$10,0) | D13: =COUNTIFS('CRM Export'!$P:$P,A13,'CRM Export'!$F:$F,"Relevant") | E13: =IFERROR(D13/B13,0) | F13: =COUNTIFS('CRM Export'!$P:$P,A13,'CRM Export'!$E:$E,"Rejected") | G13: =IFERROR(F13/B13,0) | H13: n/a | I13: n/a

Sheet Service Report
A1: Service report
A3: Service | B3: Leads | C3: Share | D3: Relevant | E3: Relevant rate | F3: Rejected | G3: Agreement status | H3: Initial payment status
A4: LT citizenship | B4: =COUNTIF('CRM Export'!$H:$H,A4) | C4: =IFERROR(B4/Dashboard!$B$10,0) | D4: =COUNTIFS('CRM Export'!$H:$H,A4,'CRM Export'!$F:$F,"Relevant") | E4: =IFERROR(D4/B4,0) | F4: =COUNTIFS('CRM Export'!$H:$H,A4,'CRM Export'!$E:$E,"Rejected") | G4: =COUNTIFS('CRM Export'!$H:$H,A4,'CRM Export'!$E:$E,"RETAINER AGREEMENT SENT") | H4: =COUNTIFS('CRM Export'!$H:$H,A4,'CRM Export'!$E:$E,"INITIAL PAYMENT RECEIVED")
A5: LV RBI Company | B5: =COUNTIF('CRM Export'!$H:$H,A5) | C5: =IFERROR(B5/Dashboard!$B$10,0) | D5: =COUNTIFS('CRM Export'!$H:$H,A5,'CRM Export'!$F:$F,"Relevant") | E5: =IFERROR(D5/B5,0) | F5: =COUNTIFS('CRM Export'!$H:$H,A5,'CRM Export'!$E:$E,"Rejected") | G5: =COUNTIFS('CRM Export'!$H:$H,A5,'CRM Export'!$E:$E,"RETAINER AGREEMENT SENT") | H5: =COUNTIFS('CRM Export'!$H:$H,A5,'CRM Export'!$E:$E,"INITIAL PAYMENT RECEIVED")
A6: LT RBI | B6: =COUNTIF('CRM Export'!$H:$H,A6) | C6: =IFERROR(B6/Dashboard!$B$10,0) | D6: =COUNTIFS('CRM Export'!$H:$H,A6,'CRM Export'!$F:$F,"Relevant") | E6: =IFERROR(D6/B6,0) | F6: =COUNTIFS('CRM Export'!$H:$H,A6,'CRM Export'!$E:$E,"Rejected") | G6: =COUNTIFS('CRM Export'!$H:$H,A6,'CRM Export'!$E:$E,"RETAINER AGREEMENT SENT") | H6: =COUNTIFS('CRM Export'!$H:$H,A6,'CRM Export'!$E:$E,"INITIAL PAYMENT RECEIVED")
A7: Company Formation | B7: =COUNTIF('CRM Export'!$H:$H,A7) | C7: =IFERROR(B7/Dashboard!$B$10,0) | D7: =COUNTIFS('CRM Export'!$H:$H,A7,'CRM Export'!$F:$F,"Relevant") | E7: =IFERROR(D7/B7,0) | F7: =COUNTIFS('CRM Export'!$H:$H,A7,'CRM Export'!$E:$E,"Rejected") | G7: =COUNTIFS('CRM Export'!$H:$H,A7,'CRM Export'!$E:$E,"RETAINER AGREEMENT SENT") | H7: =COUNTIFS('CRM Export'!$H:$H,A7,'CRM Export'!$E:$E,"INITIAL PAYMENT RECEIVED")
A8: LV citizenship | B8: =COUNTIF('CRM Export'!$H:$H,A8) | C8: =IFERROR(B8/Dashboard!$B$10,0) | D8: =COUNTIFS('CRM Export'!$H:$H,A8,'CRM Export'!$F:$F,"Relevant") | E8: =IFERROR(D8/B8,0) | F8: =COUNTIFS('CRM Export'!$H:$H,A8,'CRM Export'!$E:$E,"Rejected") | G8: =COUNTIFS('CRM Export'!$H:$H,A8,'CRM Export'!$E:$E,"RETAINER AGREEMENT SENT") | H8: =COUNTIFS('CRM Export'!$H:$H,A8,'CRM Export'!$E:$E,"INITIAL PAYMENT RECEIVED")
A9: 50/50 | B9: =COUNTIF('CRM Export'!$H:$H,A9) | C9: =IFERROR(B9/Dashboard!$B$10,0) | D9: =COUNTIFS('CRM Export'!$H:$H,A9,'CRM Export'!$F:$F,"Relevant") | E9: =IFERROR(D9/B9,0) | F9: =COUNTIFS('CRM Export'!$H:$H,A9,'CRM Export'!$E:$E,"Rejected") | G9: =COUNTIFS('CRM Export'!$H:$H,A9,'CRM Export'!$E:$E,"RETAINER AGREEMENT SENT") | H9: =COUNTIFS('CRM Export'!$H:$H,A9,'CRM Export'!$E:$E,"INITIAL PAYMENT RECEIVED")
A10: LV RBI Real Estate | B10: =COUNTIF('CRM Export'!$H:$H,A10) | C10: =IFERROR(B10/Dashboard!$B$10,0) | D10: =COUNTIFS('CRM Export'!$H:$H,A10,'CRM Export'!$F:$F,"Relevant") | E10: =IFERROR(D10/B10,0) | F10: =COUNTIFS('CRM Export'!$H:$H,A10,'CRM Export'!$E:$E,"Rejected") | G10: =COUNTIFS('CRM Export'!$H:$H,A10,'CRM Export'!$E:$E,"RETAINER AGREEMENT SENT") | H10: =COUNTIFS('CRM Export'!$H:$H,A10,'CRM Export'!$E:$E,"INITIAL PAYMENT RECEIVED")
A11: Partnership | B11: =COUNTIF('CRM Export'!$H:$H,A11) | C11: =IFERROR(B11/Dashboard!$B$10,0) | D11: =COUNTIFS('CRM Export'!$H:$H,A11,'CRM Export'!$F:$F,"Relevant") | E11: =IFERROR(D11/B11,0) | F11: =COUNTIFS('CRM Export'!$H:$H,A11,'CRM Export'!$E:$E,"Rejected") | G11: =COUNTIFS('CRM Export'!$H:$H,A11,'CRM Export'!$E:$E,"RETAINER AGREEMENT SENT") | H11: =COUNTIFS('CRM Export'!$H:$H,A11,'CRM Export'!$E:$E,"INITIAL PAYMENT RECEIVED")

Sheet Pipeline & Quality
A1: Pipeline and data quality
A3: Current status distribution | E3: Field completeness
A4: Value | B4: Count | C4: Share | E4: Field | F4: Filled rows | G4: Fill rate
A5: Rejected | B5: =COUNTIF('CRM Export'!$E:$E,A5) | C5: =IFERROR(B5/Dashboard!$B$10,0) | E5: Relevant | F5: =COUNTIF('CRM Export'!$F:$F,"<>")-1 | G5: =IFERROR(F5/Dashboard!$B$10,0)
A6: IN WORK | B6: =COUNTIF('CRM Export'!$E:$E,A6) | C6: =IFERROR(B6/Dashboard!$B$10,0) | E6: Service (group) | F6: =COUNTIF('CRM Export'!$H:$H,"<>")-1 | G6: =IFERROR(F6/Dashboard!$B$10,0)
A7: FIRST CONTACT | B7: =COUNTIF('CRM Export'!$E:$E,A7) | C7: =IFERROR(B7/Dashboard!$B$10,0) | E7: Country | F7: =COUNTIF('CRM Export'!$I:$I,"<>")-1 | G7: =IFERROR(F7/Dashboard!$B$10,0)
A8: RETAINER AGREEMENT SENT | B8: =COUNTIF('CRM Export'!$E:$E,A8) | C8: =IFERROR(B8/Dashboard!$B$10,0) | E8: UTM tag | F8: =COUNTIF('CRM Export'!$J:$J,"<>")-1 | G8: =IFERROR(F8/Dashboard!$B$10,0)
A9: INITIAL PAYMENT RECEIVED | B9: =COUNTIF('CRM Export'!$E:$E,A9) | C9: =IFERROR(B9/Dashboard!$B$10,0) | E9: Google Client ID | F9: =COUNTIF('CRM Export'!$K:$K,"<>")-1 | G9: =IFERROR(F9/Dashboard!$B$10,0)
A10: FULL PAYMENT IS MADE | B10: =COUNTIF('CRM Export'!$E:$E,A10) | C10: =IFERROR(B10/Dashboard!$B$10,0) | E10: Language | F10: =COUNTIF('CRM Export'!$L:$L,"<>")-1 | G10: =IFERROR(F10/Dashboard!$B$10,0)
A11: Завершене | B11: =COUNTIF('CRM Export'!$E:$E,A11) | C11: =IFERROR(B11/Dashboard!$B$10,0) | E11: Email | F11: =COUNTIF('CRM Export'!$N:$N,"<>")-1 | G11: =IFERROR(F11/Dashboard!$B$10,0)
A12: WHATSAPP | B12: =COUNTIF('CRM Export'!$E:$E,A12) | C12: =IFERROR(B12/Dashboard!$B$10,0) | E12: Source | F12: =COUNTIF('CRM Export'!$P:$P,"<>")-1 | G12: =IFERROR(F12/Dashboard!$B$10,0)
A13: INTERNAL MAIL | B13: =COUNTIF('CRM Export'!$E:$E,A13) | C13: =IFERROR(B13/Dashboard!$B$10,0) | E13: Date completed | F13: =COUNTIF('CRM Export'!$U:$U,"<>")-1 | G13: =IFERROR(F13/Dashboard!$B$10,0)
A14: NEW | B14: =COUNTIF('CRM Export'!$E:$E,A14) | C14: =IFERROR(B14/Dashboard!$B$10,0) | E14: agreement_sent_at | F14: =COUNTIF('CRM Export'!$V:$V,"<>")-1 | G14: =IFERROR(F14/Dashboard!$B$10,0)
A15: PAUSED | B15: =COUNTIF('CRM Export'!$E:$E,A15) | C15: =IFERROR(B15/Dashboard!$B$10,0) | E15: currency | F15: =COUNTIF('CRM Export'!$W:$W,"<>")-1 | G15: =IFERROR(F15/Dashboard!$B$10,0)
A16: 2ND INSTALLMENT RECEIVED | B16: =COUNTIF('CRM Export'!$E:$E,A16) | C16: =IFERROR(B16/Dashboard!$B$10,0) | E16: agreement_signed_at | F16: =COUNTIF('CRM Export'!$X:$X,"<>")-1 | G16: =IFERROR(F16/Dashboard!$B$10,0)
E17: deal_value_actual | F17: =COUNTIF('CRM Export'!$Z:$Z,"<>")-1 | G17: =IFERROR(F17/Dashboard!$B$10,0)
A19: Rejection reasons
A20: Value | B20: Count | C20: Share
A21: Non-relevant lead | B21: =COUNTIF('CRM Export'!$O:$O,A21) | C21: =IFERROR(B21/COUNTIF('CRM Export'!$O:$O,"<>")-1,0)
A22: NO ANSWER | B22: =COUNTIF('CRM Export'!$O:$O,A22) | C22: =IFERROR(B22/COUNTIF('CRM Export'!$O:$O,"<>")-1,0)
A23: DOUBLE | B23: =COUNTIF('CRM Export'!$O:$O,A23) | C23: =IFERROR(B23/COUNTIF('CRM Export'!$O:$O,"<>")-1,0)
A24: ANOTHER REASON | B24: =COUNTIF('CRM Export'!$O:$O,A24) | C24: =IFERROR(B24/COUNTIF('CRM Export'!$O:$O,"<>")-1,0)
A25: LEFT BEFORE 1918 | B25: =COUNTIF('CRM Export'!$O:$O,A25) | C25: =IFERROR(B25/COUNTIF('CRM Export'!$O:$O,"<>")-1,0)
A26: TOO EXPENSIVE | B26: =COUNTIF('CRM Export'!$O:$O,A26) | C26: =IFERROR(B26/COUNTIF('CRM Export'!$O:$O,"<>")-1,0)
A27: DID NOT CONTINUE | B27: =COUNTIF('CRM Export'!$O:$O,A27) | C27: =IFERROR(B27/COUNTIF('CRM Export'!$O:$O,"<>")-1,0)
A28: SPAM | B28: =COUNTIF('CRM Export'!$O:$O,A28) | C28: =IFERROR(B28/COUNTIF('CRM Export'!$O:$O,"<>")-1,0)
A29: NO ANCESTORS | B29: =COUNTIF('CRM Export'!$O:$O,A29) | C29: =IFERROR(B29/COUNTIF('CRM Export'!$O:$O,"<>")-1,0)
A30: APPLIED BY THEMSELVES | B30: =COUNTIF('CRM Export'!$O:$O,A30) | C30: =IFERROR(B30/COUNTIF('CRM Export'!$O:$O,"<>")-1,0)
A31: VILNIUS | B31: =COUNTIF('CRM Export'!$O:$O,A31) | C31: =IFERROR(B31/COUNTIF('CRM Export'!$O:$O,"<>")-1,0)
A32: CRM MISTAKE | B32: =COUNTIF('CRM Export'!$O:$O,A32) | C32: =IFERROR(B32/COUNTIF('CRM Export'!$O:$O,"<>")-1,0)

Sheet Field Coverage
A1: Agreed fields vs current export
A3: Block | B3: Field | C3: Current situation | D3: In current export? | E3: Usable now? | F3: Comment | H3: Key interpretation
A4: Identification | B4: lead_id | C4: Номер | D4: Yes | E4: Yes | F4: Used as lead identifier | H4: Yes = field exists and can already be used
A5: Identification | B5: contact_id / client_id | C5: Контрагент | D5: Partial | E5: Partial | F5: Contact exists, but client-level logic still needs clarification | H5: Partial = field exists but still incomplete / limited / messy
A6: Identification | B6: parent_lead_id | C6: Missing | D6: No | E6: No | F6: Not present in current export | H6: No = field is missing from this export
A7: Identification | B7: duplicate_flag | C7: Missing | D7: No | E7: No | F7: Not present in current export
A8: Basic | B8: lead_created_at | C8: Дата створення | D8: Yes | E8: Yes | F8: Ready
A9: Basic | B9: owner / sales_manager | C9: Виконавці | D9: Yes | E9: Yes | F9: Ready
A10: Basic | B10: full_name | C10: Назва | D10: Yes | E10: Yes | F10: Ready
A11: Basic | B11: email | C11: E-mail Counterparty | D11: Yes | E11: Yes | F11: Ready
A12: Basic | B12: phone | C12: Not exported | D12: No | E12: No | F12: Phone is not in current export
A13: Basic | B13: backup_phone | C13: Not exported | D13: No | E13: No | F13: Missing
A14: Basic | B14: country | C14: Country | D14: Yes | E14: Yes | F14: Ready
A15: Basic | B15: language | C15: LANGUAGE | D15: Yes | E15: Yes | F15: Ready
A16: Basic | B16: initial_inquiry_notes | C16: Not exported separately | D16: No | E16: No | F16: No dedicated field
A17: Attribution | B17: first_touch_source | C17: Name (source) | D17: Yes | E17: Yes | F17: Usable as source now
A18: Attribution | B18: first_touch_medium | C18: utm_medium | D18: Yes | E18: No | F18: Column exists but empty
... A57: Money | B57: deal_value_actual | C57: deal_value_actual | D57: Yes | E57: No | F57: Column exists but empty
