Workbook

Sheet KPI plan
A1: KPI 2025-2026 (edited in September 2025)
C2: Revenue after marketing exp. | D2: Base | E2: Expected growth | F2: Actual result | G2: Bonus calculation
A3: May | D3: 30543 | E3: 32725 | F3: 58549.47
A4: Jun | B4: 0 | C4: 48375 | D4: 30543 | E4: 35700 | F4: 25655.24 | I4: 3465 | J4: monthly revenue increase
A5: Jul | B5: 1 | C5: 51266 | D5: 48375 | E5: =C5-D5 -> 2891 | F5: ='Actual results'!E40 -> 30578.07 | G5: =(((F5-D5)+(F4-D4)+(F3-D3))/sum(E3:E5))*$I$27 -> 52.235768 | I5: 700 | J5: monthly bonus for 100% result
A6: Aug | B6: 2 | C6: 54157 | D6: 48375 | E6: =C6-D6 -> 5782 | F6: ='Actual results'!E41 -> 35109.82 | G6: =(((F6-D6)+(F5-D5)+(F4-D4))/sum(E4:E6))*$I$27 -> -567.1221 | I6: 1300 | J6: fix
A7: Sep | B7: 3 | C7: 57048 | D7: 48375 | E7: =C7-D7 -> 8673 | F7: ='Actual results'!E42 -> 34973.99 | G7: =(((F7-D7)+(F6-D6)+(F5-D5))/sum(E5:E7))*$I$27 -> -1794.3148
A8: Oct | B8: 4 | C8: 59939 | D8: 48375 | E8: =C8-D8 -> 11564 | F8: ='Actual results'!E43 -> 47679.2 | G8: =(((F8-D8)+(F7-D7)+(F6-D6))/sum(E6:E8))*$I$27 -> -736.13102
A9: Nov | B9: 5 | C9: 62830 | D9: 48375 | E9: =C9-D9 -> 14455 | F9: ='Actual results'!E44 -> 52342.56 | G9: =(((F9-D9)+(F8-D8)+(F7-D7))/sum(E7:E9))*$I$27 -> -204.38358
A10: Dec | B10: 6 | C10: 65721 | D10: 48375 | E10: =C10-D10 -> 17346 | F10: ='Actual results'!E45 -> 31849.97 | G10: =(((F10-D10)+(F9-D9)+(F8-D8))/sum(E8:E10))*$I$27 -> -213.93495
A11: Jan | B11: 7 | C11: 68612 | D11: 48375 | E11: =C11-D11 -> 20237 | F11: ='Actual results'!E46 -> 28361.75 | G11: =(((F11-D11)+(F10-D10)+(F9-D9))/sum(E9:E11))*$I$27 -> -438.13183
A12: Feb | B12: 8 | C12: 71503 | D12: 48375 | E12: =C12-D12 -> 23128 | F12: ='Actual results'!E47 -> 48192.89 | G12: =(((F12-D12)+(F11-D11)+(F10-D10))/sum(E10:E12))*$I$27 -> -423.38741
A13: Mar | B13: 9 | C13: 74394 | D13: 48375 | E13: =C13-D13 -> 26019 | F13: ='Actual results'!E48 -> 64146.75 | G13: =(((F13-D13)+(F12-D12)+(F11-D11))/sum(E11:E13))*$I$27 -> -44.628834
A14: Apr | B14: 10 | C14: 77285 | D14: 48375 | E14: =C14-D14 -> 28910 | F14: ='Actual results'!E49 -> 19847.21 | G14: =(((F14-D14)+(F13-D13)+(F12-D12))/sum(E12:E14))*$I$27 -> -116.02681
A15: May | B15: 11 | C15: 80176 | D15: 48375 | E15: =C15-D15 -> 31801 | G15: =(((F15-D15)+(F14-D14)+(F13-D13))/sum(E13:E15))*$I$27 -> -493.39015
A16: Jun | B16: 12 | C16: 83067 | D16: 48375 | E16: =C16-D16 -> 34692 | G16: =(((F16-D16)+(F15-D15)+(F14-D14))/sum(E14:E16))*$I$27 -> -919.20016
B17: Sum | C17: =SUM(C5:C16) -> 805998 | D17: =SUM(D5:D16) -> 580500 | F17: =SUM(F5:F16) -> 393082.21
E18: Percentage of the plan | F18: =F17/C17 -> 0.48769626
E20: Profit growth against the previous year | F20: =F17-F58 -> -187402.49 | G20: =F20/F58 -> -0.32283795
A23: KPI 2025-2026
C24: Revenue after marketing exp. | D24: Base | E24: Expected growth | F24: Actual result | G24: Bonus calculation
A25: May | D25: 30543 | E25: 32725 | F25: 58549.47
A26: Jun | B26: 0 | C26: 48375 | D26: 30543 | E26: 35700 | F26: 25655.24 | I26: 3465 | J26: monthly revenue increase
A27: Jul | B27: 1 | C27: 51840 | D27: 48375 | E27: =C27-D27 -> 3465 | F27: ='Actual results'!E40 -> 30578.07 | G27: =(((F27-D27)+(F26-D26)+(F25-D25))/sum(E25:E27))*$I$27 -> 51.818695 | I27: 700 | J27: monthly bonus for 100% result
A28: Aug | B28: 2 | C28: 55305 | D28: 48375 | E28: =C28-D28 -> 6930 | F28: ='Actual results'!E41 -> 35109.82 | G28: =(((F28-D28)+(F27-D27)+(F26-D26))/sum(E26:E28))*$I$27 -> -545.93576 | I28: 1300 | J28: fix
A29: Sep | B29: 3 | C29: 58770 | D29: 48375 | E29: =C29-D29 -> 10395 | G29: =(((F29-D29)+(F28-D28)+(F27-D27))/sum(E27:E29))*$I$27 -> -2674.6502
A30: Oct | B30: 4 | C30: 62235 | D30: 48375 | E30: =C30-D30 -> 13860 | G30: =(((F30-D30)+(F29-D29)+(F28-D28))/sum(E28:E30))*$I$27 -> -2469.4765
A31: Nov | B31: 5 | C31: 65700 | D31: 48375 | E31: =C31-D31 -> 17325 | G31: =(((F31-D31)+(F30-D30)+(F29-D29))/sum(E29:E31))*$I$27 -> -2443.1818
A32: Dec | B32: 6 | C32: 69165 | D32: 48375 | E32: =C32-D32 -> 20790 | G32: =(((F32-D32)+(F31-D31)+(F30-D30))/sum(E30:E32))*$I$27 -> -1954.5455
A33: Jan | B33: 7 | C33: 72630 | D33: 48375 | E33: =C33-D33 -> 24255 | G33: =(((F33-D33)+(F32-D32)+(F31-D31))/sum(E31:E33))*$I$27 -> -1628.7879
A34: Feb | B34: 8 | C34: 76095 | D34: 48375 | E34: =C34-D34 -> 27720 | G34: =(((F34-D34)+(F33-D33)+(F32-D32))/sum(E32:E34))*$I$27 -> -1396.1039
A35: Mar | B35: 9 | C35: 79560 | D35: 48375 | E35: =C35-D35 -> 31185 | G35: =(((F35-D35)+(F34-D34)+(F33-D33))/sum(E33:E35))*$I$27 -> -1221.5909
A36: Apr | B36: 10 | C36: 83025 | D36: 48375 | E36: =C36-D36 -> 34650 | G36: =(((F36-D36)+(F35-D35)+(F34-D34))/sum(E34:E36))*$I$27 -> -1085.8586
A37: May | B37: 11 | C37: 86490 | D37: 48375 | E37: =C37-D37 -> 38115 | G37: =(((F37-D37)+(F36-D36)+(F35-D35))/sum(E35:E37))*$I$27 -> -977.27273
A38: Jun | B38: 12 | C38: 89955 | D38: 48375 | E38: =C38-D38 -> 41580 | G38: =(((F38-D38)+(F37-D37)+(F36-D36))/sum(E36:E38))*$I$27 -> -888.42975
B39: Sum | C39: 850 770 | D39: 580 500
A43: KPI 2024-2025
C44: Revenue after marketing exp. | D44: Base | E44: Expected growth | F44: Actual result | G44: Bonus calculation
A45: Jun | B45: 0 | C45: 30543 | D45: 30543 | E45: =C45-D45 -> 0 | I45: 2975 | J45: monthly revenue increase
A46: Jul | B46: 1 | C46: 33518 | D46: 30543 | E46: =C46-D46 -> 2975 | F46: ='Actual results'!E28 -> 24112.03 | G46: =(F46-D46)/E46*$I$46 -> -1080.8353 | I46: 500 | J46: monthly bonus for 100% result
...

Sheet Actual results
F1: Signed contracts
A2: 2022-2025 | B2: Actual result | C2: Marketing costs | D2: Share of Marketing Costs | E2: Profit without marketing costs | F2: Total | G2: LT | H2: LV | I2: Comp.form | J2: RBI | K2: Cost per contract
A3: Jun | B3: 32603 | C3: ='Marketing cost'!R3 -> 5061.39 | D3: =C3/B3 -> 0.15524308 | E3: =B3-C3 -> 27541.61
A4: Jul | B4: 43580 | C4: ='Marketing cost'!S3 -> 5871.13 | D4: =C4/B4 -> 0.13472074 | E4: =B4-C4 -> 37708.87 | F4: =SUM(G4:J4) -> 24 | G4: 21 | H4: 2 | J4: 1 | K4: =C4/F4 -> 244.63042
A5: Aug | B5: 41775.85 | C5: ='Marketing cost'!T3 -> 7424.2381 | D5: =C5/B5 -> 0.17771603 | E5: =B5-C5 -> 34351.612 | F5: =SUM(G5:J5) -> 24 | G5: 20 | H5: 3 | J5: 1 | K5: =C5/F5 -> 309.34325
A6: Sep | B6: 18272 | C6: ='Marketing cost'!U3 -> 7153.17 | D6: =C6/B6 -> 0.3914826 | E6: =B6-C6 -> 11118.83 | F6: =SUM(G6:J6) -> 22 | G6: 19 | H6: 3 | J6: 0 | K6: =C6/F6 -> 325.14409
A7: Oct | B7: 43918 | C7: ='Marketing cost'!V3 -> 8476.17 | D7: =C7/B7 -> 0.19299991 | E7: =B7-C7 -> 35441.83 | F7: =SUM(G7:J7) -> 20 | G7: 18 | H7: 1 | J7: 1 | K7: =C7/F7 -> 423.8085
A8: Nov | B8: 33670 | C8: ='Marketing cost'!W3 -> 8469.93 | D8: =C8/B8 -> 0.25155717 | E8: =B8-C8 -> 25200.07 | F8: =SUM(G8:J8) -> 26 | G8: 21 | H8: 5 | J8: 0 | K8: =C8/F8 -> 325.76654
A9: Dec | B9: =59939+350+350 -> 60639 | C9: ='Marketing cost'!X3 -> 9383.601 | D9: =C9/B9 -> 0.15474531 | E9: =B9-C9 -> 51255.399 | F9: =SUM(G9:J9) -> 14 | G9: 11 | H9: 3 | J9: 0 | K9: =C9/F9 -> 670.25721
A10: Jan | B10: 23670 | C10: ='Marketing cost'!Y3 -> 10290.41 | D10: =C10/B10 -> 0.43474482 | E10: =B10-C10 -> 13379.59 | F10: =SUM(G10:J10) -> 20 | G10: 16 | H10: 4 | J10: 0 | K10: =C10/F10 -> 514.5205
A11: Feb | B11: 40401 | C11: ='Marketing cost'!Z3 -> 8708.72 | D11: =C11/B11 -> 0.21555704 | E11: =B11-C11 -> 31692.28 | F11: =SUM(G11:J11) -> 27 | G11: 25 | H11: 2 | J11: 0 | K11: =C11/F11 -> 322.54519
A12: Mar | B12: 11780 | C12: ='Marketing cost'!AA3 -> 9642.24 | D12: =C12/B12 -> 0.81852632 | E12: =B12-C12 -> 2137.76 | F12: =SUM(G12:J12) -> 18 | G12: 15 | H12: 3 | J12: 0 | K12: =C12/F12 -> 535.68
A13: Apr | B13: 19591 | C13: ='Marketing cost'!AB3 -> 9330.34 | D13: =C13/B13 -> 0.47625644 | E13: =B13-C13 -> 10260.66 | F13: =SUM(G13:J13) -> 17 | G13: 14 | H13: 3 | J13: 0 | K13: =C13/F13 -> 548.84353
A14: May | B14: 35612 | C14: ='Marketing cost'!AC3 -> 9312.33 | D14: =C14/B14 -> 0.26149416 | E14: =B14-C14 -> 26299.67 | F14: =SUM(G14:J14) -> 30 | G14: 27 | H14: 3 | J14: 0 | K14: =C14/F14 -> 310.411
A15: Jun | B15: 20263 | C15: ='Marketing cost'!AD3 -> 9082.11 | D15: =C15/B15 -> 0.44821152 | E15: =B15-C15 -> 11180.89 | F15: =SUM(G15:J15) -> 30 | G15: 25 | H15: 5 | J15: 0 | K15: =C15/F15 -> 302.737
A16: Jul | B16: 22214 | C16: ='Marketing cost'!AE3 -> 6757.81 | D16: =C16/B16 -> 0.30421401 | E16: =B16-C16 -> 15456.19 | F16: =SUM(G16:J16) -> 26 | G16: 23 | H16: 3 | J16: 0 | K16: =C16/F16 -> 259.91577
A17: Aug | B17: 19055 | C17: ='Marketing cost'!AF3 -> 7190.92 | D17: =C17/B17 -> 0.37737707 | E17: =B17-C17 -> 11864.08 | F17: =SUM(G17:J17) -> 29 | G17: 26 | H17: 3 | J17: 0 | K17: =C17/F17 -> 247.96276
A18: Sep | B18: 40014 | C18: ='Marketing cost'!AG3 -> 6131.18 | D18: =C18/B18 -> 0.15322587 | E18: =B18-C18 -> 33882.82 | F18: =SUM(G18:J18) -> 22 | G18: 19 | H18: 3 | J18: 0 | K18: =C18/F18 -> 278.69
A19: Oct | B19: 30831 | C19: ='Marketing cost'!AH3 -> 7267.05 | D19: =C19/B19 -> 0.23570595 | E19: =B19-C19 -> 23563.95 | F19: =SUM(G19:J19) -> 20 | G19: 14 | H19: 4 | J19: 2 | K19: =C19/F19 -> 363.3525
A20: Nov | B20: 49445 | C20: ='Marketing cost'!AI3 -> 7302.63 | D20: =C20/B20 -> 0.14769198 | E20: =B20-C20 -> 42142.37 | F20: =SUM(G20:J20) -> 20 | G20: 18 | H20: 2 | J20: 0 | K20: =C20/F20 -> 365.1315
A21: Dec | B21: 35585 | C21: ='Marketing cost'!AJ3 -> 6959.56 | D21: =C21/B21 -> 0.19557566 | E21: =B21-C21 -> 28625.44 | F21: =SUM(G21:J21) -> 22 | G21: 19 | H21: 2 | J21: 1 | K21: =C21/F21 -> 316.34364
A22: Jan | B22: 41711 | C22: 8495.25 | D22: =C22/B22 -> 0.2036693 | E22: =B22-C22 -> 33215.75 | F22: =SUM(G22:J22) -> 46 | G22: 40 | H22: 5 | J22: 1 | K22: =C22/F22 -> 184.67935
A23: Feb | B23: 45872 | C23: ='Marketing cost'!AL3 -> 6697.63 | D23: =C23/B23 -> 0.14600693 | E23: =B23-C23 -> 39174.37 | F23: =SUM(G23:J23) -> 25 | G23: 20 | H23: 5 | J23: 0 | K23: =C23/F23 -> 267.9052
A24: Mar | B24: 61332 | C24: ='Marketing cost'!AM3 -> 7531.96 | D24: =C24/B24 -> 0.12280637 | E24: =B24-C24 -> 53800.04 | F24: =SUM(G24:J24) -> 32 | G24: 27 | H24: 5 | J24: 0 | K24: =C24/F24 -> 235.37375
A25: Apr | B25: 38708 | C25: ='Marketing cost'!AN3 -> 9324.06 | D25: =C25/B25 -> 0.24088199 | E25: =B25-C25 -> 29383.94 | F25: =SUM(G25:J25) -> 27 | G25: 24 | H25: 2 | J25: 1 | K25: =C25/F25 -> 345.33556
A26: May | B26: =46659+350 -> 47009 | C26: ='Marketing cost'!AO3 -> 7111.73 | D26: =C26/B26 -> 0.15128443 | E26: =B26-C26 -> 39897.27 | F26: =SUM(G26:J26) -> 24 | G26: 22 | H26: 2 | J26: 0 | K26: =C26/F26 -> 296.32208
A27: Jun | B27: =23430+350 -> 23780 | C27: ='Marketing cost'!AP3 -> 8268.62 | D27: =C27/B27 -> 0.3477132 | E27: =B27-C27 -> 15511.38 | F27: =SUM(G27:J27) -> 18 | G27: 16 | H27: 2 | J27: 0 | K27: =C27/F27 -> 459.36778
A28: Jul | B28: =32303+350 -> 32653 | C28: ='Marketing cost'!AQ3 -> 8540.97 | D28: =C28/B28 -> 0.2615677 | E28: =B28-C28 -> 24112.03 | F28: =SUM(G28:J28) -> 34 | G28: 30 | H28: 4 | J28: 0 | K28: =C28/F28 -> 251.205
A29: Aug | B29: 49940 | C29: ='Marketing cost'!AR3 -> 7010.54 | D29: =C29/B29 -> 0.14037926 | E29: =B29-C29 -> 42929.46 | F29: =SUM(G29:J29) -> 39 | G29: 34 | H29: 5 | J29: 0 | K29: =C29/F29 -> 179.75744
A30: Sep | B30: 65447 | C30: ='Marketing cost'!AS3 -> 8031.85 | D30: =C30/B30 -> 0.12272297 | E30: =B30-C30 -> 57415.15 | F30: =SUM(G30:J30) -> 29 | G30: 24 | H30: 4 | J30: 1 | K30: =C30/F30 -> 276.96034
A31: Oct | B31: 41510 | C31: ='Marketing cost'!AT3 -> 8196.8226 | D31: =C31/B31 -> 0.19746621 | E31: =B31-C31 -> 33313.177 | F31: 28 | G31: 24 | H31: 4 | J31: 0 | K31: =C31/F31 -> 292.74366
A32: Nov | B32: =58175+3000+583 -> 61758 | C32: ='Marketing cost'!AU3 -> 7463.85 | D32: =C32/B32 -> 0.12085641 | E32: =B32-C32 -> 54294.15 | F32: =SUM(G32:J32) -> 34 | G32: 26 | H32: 8 | J32: 0 | K32: =C32/F32 -> 219.525
A33: Dec | B33: 73294 | C33: ='Marketing cost'!AV3 -> 6849.83 | D33: =C33/B33 -> 0.0934569 | E33: =B33-C33 -> 66444.17 | F33: =SUM(G33:J33) -> 16 | G33: 14 | H33: 0 | J33: 2 | K33: =C33/F33 -> 428.11437
A34: Jan | B34: 57743 | C34: ='Marketing cost'!Q3 -> 7221.14 | D34: =C34/B34 -> 0.12505654 | E34: =B34-C34 -> 50521.86 | F34: =SUM(G34:J34) -> 23 | G34: 22 | H34: 0 | J34: 1 | K34: =C34/F34 -> 313.96261
A35: Feb | B35: =61027+1599 -> 62626 | C35: ='Marketing cost'!P3 -> 6450.37 | D35: =C35/B35 -> 0.10299828 | E35: =B35-C35 -> 56175.63 | F35: =SUM(G35:J35) -> 33 | G35: 28 | H35: 2 | J35: 3 | K35: =C35/F35 -> 195.46576
A36: Mar | B36: 75054 | C36: ='Marketing cost'!O3 -> 5635.6 | D36: =C36/B36 -> 0.07508727 | E36: =B36-C36 -> 69418.4 | F36: =SUM(G36:J36) -> 22 | G36: 17 | H36: 3 | J36: 2 | K36: =C36/F36 -> 256.16364
A37: Apr | B37: =46479+370+3250 -> 50099 | C37: ='Marketing cost'!N3 -> 8443.04 | D37: =C37/B37 -> 0.16852712 | E37: =B37-C37 -> 41655.96 | F37: =SUM(G37:J37) -> 29 | G37: 22 | H37: 5 | J37: 2 | K37: =C37/F37 -> 291.13931
A38: May | B38: 69986 | C38: ='Marketing cost'!M3 -> 11436.53 | D38: =C38/B38 -> 0.16341168 | E38: =B38-C38 -> 58549.47 | F38: =SUM(G38:J38) -> 42 | G38: 27 | H38: 8 | J38: 7 | K38: =C38/F38 -> 272.29833
A39: Jun | B39: 38550 | C39: ='Marketing cost'!L3 -> 12894.76 | D39: =C39/B39 -> 0.33449442 | E39: =B39-C39 -> 25655.24 | F39: =SUM(G39:J39) -> 30 | G39: 20 | H39: 5 | J39: 5 | K39: =C39/F39 -> 429.82533
A40: Jul | B40: =41745+2040 -> 43785 | C40: ='Marketing cost'!K3 -> 13206.93 | D40: =C40/B40 -> 0.30163138 | E40: =B40-C40 -> 30578.07 | F40: =SUM(G40:J40) -> 42 | G40: 32 | H40: 8 | J40: 2 | K40: =C40/F40 -> 314.45071
...

Sheet Marketing cost
B1: =B6+B7 -> 5098.29 | C1: =C6+C7 -> 6023.55 | D1: =D6+D7 -> 5255.21 | E1: =E6+E7 -> 7473.55 | F1: =F6+F7 -> 7304.1 | G1: =G6+G7 -> 8233.71 | H1: =H6+H7 -> 8411.53 | I1: =I6+I7 -> 8673.27 | ... AV1: =AV6+AV7 -> 4830.83
Q2: 2025 | R2: 2022 | Y2: 2023 | AK2: 2024
A3: Marketing costs, EUR | B3: =SUM(B5:B26) -> 7865.79 | C3: =SUM(C5:C26) -> 8783.25 | D3: =SUM(D5:D26) -> 8477.11 | E3: =SUM(E5:E26) -> 11305.25 | F3: =SUM(F5:F26) -> 11280.03 | G3: =SUM(G5:G21) -> 12780.44 | H3: =SUM(H5:H21) -> 12569.8 | I3: =SUM(I5:I21) -> 12849.01 | J3: =SUM(J5:J21) -> 12833.18 | K3: =SUM(K5:K21) -> 13206.93 | L3: =SUM(L5:L21) -> 12894.76 | M3: =SUM(M5:M21) -> 11436.53 | N3: =SUM(N5:N21) -> 8443.04 | ... P3: =SUM(P5:P21) -> 6450.37 | Q3: =SUM(Q5:Q20) -> 7221.14 | R3: =SUM(R5:R20) -> 5061.39 | S3: =SUM(S5:S20) -> 5871.13 | T3: =SUM(T5:T20) -> 7424.2381 | U3: =SUM(U5:U20) -> 7153.17 | V3: =SUM(V5:V20) -> 8476.17 | W3: =SUM(W5:W20) -> 8469.93 | X3: =SUM(X5:X20) -> 9383.601 | ... AV3: =SUM(AV5:AV20) -> 6849.83
B4: April | C4: March | D4: February | E4: January | F4: December | G4: November | H4: October | I4: September | J4: August | K4: July | L4: June | M4: May | N4: April | O4: March | P4: February | Q4: January | R4: June | S4: July | T4: August | U4: September | V4: October | W4: November | X4: December | Y4: January | Z4: February | AA4: March | AB4: April | AC4: May | AD4: June | AE4: July | AF4: August | AG4: September | AH4: October | AI4: November | AJ4: December | AK4: January | AL4: February | AM4: March | AN4: April | AO4: May | AP4: June | AQ4: July | AR4: August | AS4: September | AT4: October | AU4: November | AV4: December
A5: FB & Instagram | R5: 2094.86 | S5: 2564.76 | T5: 2494.73 | U5: 2567.05 | V5: 3332.06 | W5: 3439.18 | X5: 4860.21 | Y5: 6996.3 | Z5: 6185.81 | AA5: 6847.29 | AB5: 5292.45 | AC5: 3214.07 | AD5: =1864.27 -> 1864.27 | AE5: 0 | AF5: 0 | AG5: 0 | AH5: 0
A6: Google | B6: 4940.93 | C6: 5898.88 | D6: 5064.66 | E6: 7256.44 | F6: 7087.18 | G6: 7987.56 | H6: 8138.32 | I6: 8412.36 | J6: 8878.71 | K6: 9294.25 | L6: 9153.27 | M6: 7954.88 | N6: 4910.67 | O6: 2899.81 | P6: 2561.49 | Q6: 4241.64 | R6: 856.7 | S6: 862.99 | T6: 863.14 | U6: 973.96 | V6: 1507.19 | W6: 1675.53 | X6: 1528.06 | Y6: 844.89 | Z6: 1327.91 | AA6: 1421.95 | AB6: 2842.89 | AC6: 4359.97 | AD6: =5472.99 -> 5472.99 | AE6: 5184.81 | AF6: 4908.42 | AG6: 4188.18 | AH6: 4563.05 | AI6: 5043.24 | AJ6: 4645.2 | AK6: 6203.33 | AL6: 5301.31 | AM6: 5610.8 | AN6: 7230.99 | AO6: 5801.13 | AP6: 6342.64 | AQ6: 7020.15 | AR6: 5639.53 | AS6: 5406.79 | AT6: 5194.62 | AU6: =5783.22 -> 5783.22 | AV6: 4709.67
A7: Bing | B7: 157.36 | C7: 124.67 | D7: 190.55 | E7: 217.11 | F7: 216.92 | G7: 246.15 | H7: 273.21 | I7: 260.91 | J7: 352.59 | K7: 263.03 | L7: 231.67 | M7: 229.65 | N7: 324.37 | O7: 384.79 | P7: 314.98 | Q7: 259.5 | AH7: 400 | AI7: 578.39 | AJ7: 290.86 | AK7: 87.92 | AL7: 137.32 | AM7: 112.16 | AN7: 123.07 | AO7: 128.6 | AP7: 157.98 | AQ7: 144.82 | AR7: 150.01 | AS7: 122.61 | AT7: 128.76 | AU7: 238.63 | AV7: 121.16
A8: SEO (work) | R8: 1039.5 | S8: 1336 | T8: 1575 | U8: 1260 | V8: 1651.64 | W8: 1651.64 | X8: 1046.21 | Y8: 0 | Z8: 0 | AC8: 385 | AE8: 385 | AF8: 385 | AG8: 385 | AH8: 385
A9: SEO (backlinks) | B9: 408.5 | C9: 408.5 | D9: =254+120 -> 374 | E9: 709 | F9: 682 | G9: =550+133 -> 683 | H9: 0 | I9: 467 | K9: 530 | L9: 500 | M9: =19+190 -> 209 | AD9: 385.5 | AF9: 596 | AG9: 420 | AI9: 545 | AJ9: 400 | AK9: 400 | AL9: 0 | AM9: 400 | AN9: 500 | AP9: 400
A10: Copywriting | B10: 515 | C10: 515 | D10: =415+350 -> 765 | E10: =500+415 -> 915 | F10: =477+515 -> 992 | G10: =500+515 -> 1015 | H10: =450+515 -> 965 | I10: =429+450 -> 879 | J10: 550.5 | K10: 415 | L10: 60 | R10: 81.83 | S10: 86.65 | T10: 161.63 | U10: 173.63 | V10: 111.7 | W10: 0 | X10: =57.17+84 -> 141.17 | Y10: 0 | Z10: 0 | AC10: 190.29 | AD10: 105.35
A11: Selzy | R11: 28.5 | S11: 0 | T11: 0 | U11: 0 | V11: 105 | W11: 0 | X11: 0 | Y11: 0 | Z11: 0
A12: Marketplace fee | O12: =O17*0.05 -> 4 | Q12: =Q17*0.05 -> 4 | T12: 86.83 | U12: =63+8.67 -> 71.67 | V12: 82.58 | W12: 82.58 | X12: 52.31 | Y12: 0 | Z12: 0 | AS12: =AS17*0.05 -> 11.45 | AT12: =AT17*0.05 -> 4 | AU12: =AU17*0.05 -> 5
A13: Marketer`s salary for the previous month | B13: 389 | C13: 396 | D13: 465 | E13: 493 | F13: 340 | G13: 1300 | H13: 1300 | I13: 1300 | J13: 1351.82 | K13: 1200 | L13: 1628 | M13: 1387 | N13: 1926 | O13: 1739 | P13: 2530 | Q13: 2225 | R13: 930 | S13: 930 | T13: 2072 | U13: 1458 | V13: 1115 | W13: 1327 | X13: 1119 | Y13: 2038 | Z13: 1115 | AA13: 1203 | AB13: 1115 | AC13: 1115 | AD13: 1128 | AE13: 1115 | AF13: 1115 | AG13: 1115 | AH13: 1426 | AI13: 1115 | AJ13: 1426 | AK13: 1783 | AL13: 1238 | AM13: 1300 | AN13: 1449 | AO13: 1161 | AP13: 1257 | AQ13: 1115 | AR13: 1200 | AS13: 2241 | AT13: =1200+'KPI plan'!G48 -> 2705.4426 | AU13: 1316 | AV13: 1998
A14: Development | E14: 78 | F14: =52.85+286 -> 338.85 | H14: =324.42+77.14 -> 401.56 | I14: 147.64 | J14: 189.56 | K14: =58.33 -> 58.33 | L14: 14.82 | M14: 465 | O14: 200 | P14: 0 | T14: 160 | U14: 430 | V14: 446 | W14: 255 | X14: =1800/38.78+4000/38.944+2000/38.885 -> 200.56098 | Y14: =240 -> 240 | AA14: 90 | AC14: 25 | AD14: =41+30+32 -> 103 | AE14: =12.5+12.5+25 -> 50 | AF14: =12.5+151 -> 163.5 | AH14: =170+100+200 -> 470 | AJ14: =22.5+154 -> 176.5 | AM14: 88 | AP14: 90 | AQ14: 90
A15: Designer | T15: =400/36.67 -> 10.908099 | U15: =17.05+20 -> 37.05 | X15: =150+154 -> 304 | Y15: 102
A16: CRM | B16: 52 | C16: 37.2 | D16: =37.2+46.7 -> 83.9 | E16: =37.2+20.5 -> 57.7 | F16: =39.08+37 -> 76.08 | G16: =163.53+37.2 -> 200.73 | H16: =37.2+70.51 -> 107.71 | I16: =131.46+44.64 -> 176.1 | J16: =240+21 -> 261 | K16: =21+22.32+300 -> 343.32 | L16: 21 | M16: 21 | N16: 21 | O16: =21+15 -> 36 | P16: 42 | Q16: 21 | X16: =57+18+12.91+38+5.07+1.1 -> 132.08 | Y16: 69.22 | Z16: 80 | AA16: 80 | AB16: 80 | AC16: 23 | AD16: 23 | AE16: 23 | AF16: 23 | AG16: 23 | AH16: 23 | AI16: 21 | AJ16: 21 | AK16: 21 | AL16: 21 | AM16: 21 | AN16: 21 | AO16: 21 | AP16: 21 | AQ16: 21 | AR16: 21 | AS16: 21 | AT16: 21 | AU16: 21 | AV16: 21
A17: Other costs | F17: 112 | O17: =80 -> 80 | Q17: =80 -> 80 | R17: 30 | S17: 90.73 | T17: 0 | U17: =125+56.81 -> 181.81 | V17: 125 | W17: 39 | Y17: 0 | Z17: 0 | AQ17: 150 | AS17: =80+33+36+80 -> 229 | AT17: =80 -> 80 | AU17: =100 -> 100
A18: clickcease.com | AT18: 63
A19: Netpeak | Q19: 40
A20: SEO manager | B20: 1094 | C20: 1094 | D20: 1113 | E20: 1088 | F20: 1057 | G20: 1148 | H20: 1094 | I20: 1006 | J20: 849 | K20: 1103 | L20: 970 | M20: 970 | N20: 971 | O20: 292 | P20: 765.5 | Q20: 350
A21: BridgeWest | B21: 200 | C21: 200 | D21: 200 | E21: 200 | F21: 200 | G21: 200 | H21: 290 | I21: 200 | J21: 400 | L21: 316 | M21: 200 | N21: 290 | P21: 236.4
A22: SERanking | P22: 926.55
A23: SMM | B23: 109 | C23: 109 | D23: =221 -> 221 | E23: 291 | F23: 178

Sheet Charts
B1: 2026
B2: Jan | C2: Feb | D2: Mar | E2: Apr | F2: May | G2: Jun | H2: Jul | I2: Aug | J2: Sep | K2: Oct | L2: Nov | M2: Dec | N2: Total | O2: Percentage
A3: Net sales | B3: 73750 | C3: 97400 | D3: 73410 | E3: 44300 | N3: =SUM(B3:M3) -> 288860
A4: Transferred | B4: 39667 | C4: ='Actual results'!B47 -> 56670 | D4: 72930 | E4: 27713 | N4: =SUM(B4:M4) -> 196980 | O4: =N4/N3 -> 0.68192204
B23: 2025
B24: Jan | C24: Feb | D24: Mar | E24: Apr | F24: May | G24: Jun | H24: Jul | I24: Aug | J24: Sep | K24: Oct | L24: Nov | M24: Dec | N24: Total | O24: Percentage
A25: Net sales | B25: 56150 | C25: 124700 | D25: 46570 | E25: 63200 | F25: 107750 | G25: 85850 | H25: 120450 | I25: 68300 | J25: 95050 | K25: 88650 | L25: 58500 | M25: 42850 | N25: =SUM(B25:M25) -> 958020
A26: Transferred | B26: 57743 | C26: ='Actual results'!B35 -> 62626 | D26: ='Actual results'!B36 -> 75054 | E26: ='Actual results'!B37 -> 50099 | F26: 69986 | G26: 38550 | H26: 43785 | I26: 47943 | J26: 47823 | K26: 60249 | L26: 65123 | M26: 43130 | N26: =SUM(B26:M26) -> 662111 | O26: =N26/N25 -> 0.6911244
B45: 2024 | Q45: Net sales
B46: Jan | C46: Feb | D46: Mar | E46: Apr | F46: May | G46: Jun | H46: Jul | I46: Aug | J46: Sep | K46: Oct | L46: Nov | M46: Dec | N46: Total | O46: Percentage | R46: 2022 | S46: 2023 | T46: 2024 | U46: 2025 | V46: 2026
A47: Net sales | B47: 118930 | C47: 57150 | D47: 90500 | E47: 70650 | F47: 40250 | G47: 71972 | H47: 64050 | I47: 112310 | J47: 63850 | K47: 60200 | L47: 60790 | M47: 54270 | N47: =SUM(B47:M47) -> 864922 | Q47: Jan | R47: 66700 | S47: 44600 | T47: 118930 | U47: =B25 -> 56150 | V47: =B3 -> 73750
A48: Transferred | B48: 41711 | C48: 45872 | D48: 61332 | E48: 38708 | F48: 47009 | G48: 23780 | H48: 32653 | I48: 49940 | J48: 65447 | K48: 41510 | L48: 61758 | M48: 73294 | N48: =SUM(B48:M48) -> 583014 | O48: =N48/N47 -> 0.67406541 | Q48: Feb | R48: 61300 | S48: 77850 | T48: 57150 | U48: =C25 -> 124700 | V48: =C3 -> 97400
Q49: Mar | R49: 52482 | S49: 36100 | T49: 90500 | U49: =D25 -> 46570 | V49: =D3 -> 73410
Q50: Apr | R50: 32200 | S50: 36900 | T50: 70650 | U50: =E25 -> 63200 | V50: =E3 -> 44300
Q51: May | R51: 45450 | S51: 84650 | T51: 40250 | U51: 107750
Q52: Jun | R52: 82300 | S52: 77300 | T52: 71972 | U52: =G25 -> 85850
Q53: Jul | R53: 79285 | S53: 66250 | T53: 64050 | U53: =H25 -> 120450
Q54: Aug | R54: 82750 | S54: 79301 | T54: 112310 | U54: =I25 -> 68300
Q55: Sep | R55: 65550 | S55: 73800 | T55: 63850 | U55: =J25 -> 95050
Q56: Oct | R56: 62800 | S56: 56589 | T56: 60200 | U56: =K25 -> 88650
Q57: Nov | R57: 69123 | S57: 60790 | T57: 60790 | U57: =L25 -> 58500
Q58: Dec | R58: 26700 | S58: 75973 | T58: 54270 | U58: =M25 -> 42850
R60: =SUM(R47:R58) -> 726640 | S60: =SUM(S47:S58) -> 770103 | T60: =SUM(T47:T58) -> 864922 | U60: =SUM(U47:U58) -> 958020 | V60: =SUM(V47:V58) -> 288860
S61: =(S60-R60)/R60 -> 0.059813663 | T61: =(T60-S60)/S60 -> 0.12312509 | U61: =(U60-T60)/T60 -> 0.10763745
Q65: Transferred
R66: 2022 | S66: 2023 | T66: 2024 | U66: 2025 | V66: 2026
B67: 2023 | Q67: Jan | R67: 33624 | S67: 23670 | T67: 41711 | U67: =B26 -> 57743 | V67: =B4 -> 39667
B68: Jan | C68: Feb | D68: Mar | E68: Apr | F68: May | G68: Jun | H68: Jul | I68: Aug | J68: Sep | K68: Oct | L68: Nov | M68: Dec | N68: Total | O68: Percentage | Q68: Feb | R68: 31277 | S68: 40401 | T68: 45872 | U68: =C26 -> 62626 | V68: =C4 -> 56670
A69: Net sales | B69: 44600 | C69: 77850 | D69: 36100 | E69: 36900 | F69: 84650 | G69: 77300 | H69: 66250 | I69: 79301 | J69: 73800 | K69: 56589 | L69: 60790 | M69: 75973 | N69: =SUM(B69:M69) -> 770103 | Q69: Mar | R69: 30052 | S69: 13720 | T69: 61332 | U69: =D26 -> 75054 | V69: =D4 -> 72930
A70: Transferred | B70: 23670 | C70: 40401 | D70: 13720 | E70: 19681 | F70: 40092 | G70: 21393 | H70: 22214 | I70: 19055 | J70: 40014 | K70: 30831 | L70: 49445 | M70: 35247 | N70: =SUM(B70:M70) -> 355763 | O70: =N70/N69 -> 0.46196807 | Q70: Apr | R70: 30420 | S70: 19681 | T70: 38708 | U70: =E26 -> 50099 | V70: =E4 -> 27713
Q71: May | R71: 24867 | S71: 40092 | T71: 47009 | U71: 69986
Q72: Jun | R72: 32603 | S72: 21393 | T72: 23780 | U72: =G26 -> 38550
Q73: Jul | R73: 43580 | S73: 22214 | T73: 32653 | U73: =H26 -> 43785
Q74: Aug | R74: 42222 | S74: 19055 | T74: 49940 | U74: =I26 -> 47943
Q75: Sep | R75: 18272 | S75: 40014 | T75: 65447 | U75: =J26 -> 47823
Q76: Oct | R76: 43918 | S76: 30831 | T76: 41510 | U76: =K26 -> 60249
Q77: Nov | R77: 33670 | S77: 49445 | T77: 61758 | U77: =L26 -> 65123
Q78: Dec | R78: 60639 | S78: 35247 | T78: 73294 | U78: =M26 -> 43130
R80: =SUM(R67:R78) -> 425144 | S80: =SUM(S67:S78) -> 355763 | T80: =SUM(T67:T78) -> 583014 | U80: =SUM(U67:U78) -> 662111 | V80: =SUM(V67:V78) -> 196980
S81: =(S80-R80)/R80 -> -0.16319412 | T81: =(T80-S80)/S80 -> 0.63877075 | U81: =(U80-T80)/T80 -> 0.13566913
...
